Workbook

Sheet XP
A1: EXTRATO FINANCEIRO XP
A2: DATA | B2: DINHEIRO | C2: ATIVO | D2: COTAS | E2: VLR COTA | F2: TOTAL | G2: TX CBLC | H2: TX BOVESPA | I2: CORRETAGEM | J2: VLR TOTAL | K2: CUSTODIA | L2: TED | M2: RENDA FI | N2: DIVIDENDOS | O2: JCP | P2: RENDIMENTOS | Q2: IR | R2: SALDO DA CONTA
A3: 41330 | B3: 2000 | C3: BCFF11B | D3: 15 | E3: 129 | F3: =D3*E3 -> 1935 | G3: 0.11 | H3: 1.31 | I3: 31.13 | J3: =SUM(F3:I3) -> 1967.55 | R3: =B3-J3-K3-L3+M3+N3+O3+P3 -> 32.45
A4: 41339 | B4: 1000 | C4: BCFF11B | D4: 7 | E4: 131.69 | F4: =D4*E4 -> 921.83 | G4: 0.05 | H4: 0.62 | I4: 17.26 | J4: =SUM(F4:I4) -> 939.76 | R4: =R3+B4-J4-K4-L4+M4+N4+O4+P4 -> 92.69
A5: 41347 | C5: BCFF11B | M5: 18.34 | R5: =R4+B5-J5-K5-L5+M5+N5+O5+P5 -> 111.03
A6: 41365 | K6: 6.9 | R6: =R5+B6-J6-K6-L6+M6+N6+O6+P6 -> 104.13
A7: 41376 | C7: BCFF11B | M7: 18.43 | R7: =R6+B7-J7-K7-L7+M7+N7+O7+P7 -> 122.56
A8: 41396 | K8: 6.9 | R8: =R7+B8-J8-K8-L8+M8+N8+O8+P8 -> 115.66
A9: 41409 | C9: BCFF11B | M9: 15.66 | R9: =R8+B9-J9-K9-L9+M9+N9+O9+P9 -> 131.32
A10: 41428 | K10: 6.9 | R10: =R9+B10-J10-K10-L10+M10+N10+O10+P10 -> 124.42
A11: 41439 | C11: BCFF11B | M11: 15.33 | R11: =R10+B11-J11-K11-L11+M11+N11+O11+P11 -> 139.75
A12: 41445 | B12: 2000 | C12: BBAS3 | D12: 100 | E12: 20.85 | F12: =D12*E12 -> 2085 | G12: 0.57 | H12: 0.1 | I12: 0 | J12: =SUM(F12:I12) -> 2085.67 | R12: =R11+B12-J12-K12-L12+M12+N12+O12+P12 -> 54.08
A13: 41456 | K13: 6.9 | R13: =R12+B13-J13-K13-L13+M13+N13+O13+P13 -> 47.18
A14: 41470 | C14: BCFF11B | M14: 15.55 | R14: =R13+B14-J14-K14-L14+M14+N14+O14+P14 -> 62.73
A15: 41477 | C15: BCFF11B | D15: -22 | E15: 98.5 | F15: =(D15*E15) -> -2167 | G15: 0.13 | H15: 1.47 | I15: 0 | J15: =SUM(F15:I15) -> -2165.4 | R15: =R14+B15-J15-K15-L15+M15+N15+O15+P15 -> 2228.13
A16: 41479 | C16: SULA11 | D16: 100 | E16: 13.57 | F16: =D16*E16 -> 1357 | G16: 0.37 | H16: 0.06 | I16: 0 | J16: =SUM(F16:I16) -> 1357.43 | R16: =R15+B16-J16-K16-L16+M16+N16+O16+P16 -> 870.7
A17: 41484 | C17: ELET3 | D17: 100 | E17: 4.86 | F17: =D17*E17 -> 486 | J17: =SUM(F17:I17) -> 486 | R17: =R16+B17-J17-K17-L17+M17+N17+O17+P17 -> 384.7
A18: 41484 | B18: 600 | C18: ODPV3 | D18: 100 | E18: 9.5 | F18: =D18*E18 -> 950 | G18: 0.39 | H18: 0.07 | J18: =SUM(F18:I18) -> 950.46 | R18: =R17+B18-J18-K18-L18+M18+N18+O18+P18 -> 34.24
A19: 41487 | K19: 6.9 | R19: =R18+B19-J19-K19-L19+M19+N19+O19+P19 -> 27.34
A20: 41501 | B20: 2400 | C20: SULA11 | N20: 3.6 | R20: =R19+B20-J20-K20-L20+M20+N20+O20+P20 -> 2430.94
A21: 41502 | C21: BBAS3 | D21: 100 | E21: 23.07 | F21: =D21*E21 -> 2307 | G21: 0.63 | H21: 0.11 | I21: 15.77 | J21: =SUM(F21:I21) -> 2323.51 | R21: =R20+B21-J21-K21-L21+M21+N21+O21+P21 -> 107.43
A22: 41505 | C22: OIBR3 | D22: 300 | E22: 4.25 | F22: =D22*E22 -> 1275 | G22: 0.35 | H22: 0.06 | I22: 15.77 | J22: =SUM(F22:I22) -> 1291.18 | R22: =R21+B22-J22-K22-L22+M22+N22+O22+P22 -> -1183.75
A23: 41506 | B23: 1300 | F23: =D23*E23 -> 0 | J23: =SUM(F23:I23) -> 0 | R23: =R22+B23-J23-K23-L23+M23+N23+O23+P23 -> 116.25
A24: 41513 | C24: BVMF3 | D24: 100 | E24: 11.54 | F24: =D24*E24 -> 1154 | G24: 0.31 | H24: 0.05 | I24: 94.66 | J24: =SUM(F24:I24) -> 1249.02 | R24: =R23+B24-J24-K24-L24+M24+N24+O24+P24 -> -1132.77
A25: 41515 | B25: 1100 | R25: =R24+B25-J25-K25-L25+M25+N25+O25+P25 -> -32.77
A26: 41516 | C26: BBAS3 | N26: 153.96 | P26: 1.71 | Q26: 0.5 | R26: =R25+B26-J26-K26-L26+M26+N26+O26+P26 -> 122.9
A27: 41519 | K27: 6.9 | R27: =R26+B27-J27-K27-L27+M27+N27+O27+P27 -> 116
A28: 41521 | C28: ODPV3 | N28: 5.87 | R28: =R27+B28-J28-K28-L28+M28+N28+O28+P28 -> 121.87
A29: 41535 | C29: CMIG3 | D29: 100 | E29: 18.38 | F29: =D29*E29 -> 1838 | G29: 0.5 | H29: 0.09 | I29: 15.77 | J29: =SUM(F29:I29) -> 1854.36 | R29: =R28+B29-J29-K29-L29+M29+N29+O29+P29 -> -1732.49
A30: 41536 | B30: 1750 | R30: =R29+B30-J30-K30-L30+M30+N30+O30+P30 -> 17.51
A31: 41543 | C31: OIBR3 | D31: 200 | E31: 4.86 | F31: =D31*E31 -> 972 | G31: 0.26 | H31: 0.04 | I31: 15.77 | J31: =SUM(F31:I31) -> 988.07 | R31: =R30+B31-J31-K31-L31+M31+N31+O31+P31 -> -970.56
A32: 41544 | R32: =R31+B32-J32-K32-L32+M32+N32+O32+P32 -> -970.56
A33: 41547 | C33: BBAS3 | O33: 53.34 | Q33: 9.41 | R33: =R32+B33-J33-K33-L33+M33+N33+O33+P33 -> -917.22
A34: 41549 | B34: 1000 | K34: 2.75 | R34: =R33+B34-J34-K34-L34+M34+N34+O34+P34 -> 80.03
A35: 41549 | K35: 6.9 | R35: =R34+B35-J35-K35-L35+M35+N35+O35+P35 -> 73.13
A36: 41558 | C36: OIBR3 | N36: 152.43 | R36: =R35+B36-J36-K36-L36+M36+N36+O36+P36 -> 225.56
A37: 41572 | C37: ELET3 | D37: 50 | E37: 7.3 | F37: =D37*E37 -> 365 | G37: 0.1 | H37: 0.01 | I37: 7.72 | J37: =SUM(F37:I37) -> 372.83 | R37: =R36+B37-J37-K37-L37+M37+N37+O37+P37 -> -147.27
A38: 41575 | B38: 200 | R38: =R37+B38-J38-K38-L38+M38+N38+O38+P38 -> 52.73
A39: 41576 | B39: 2100 | C39: ELPL4 | D39: 200 | E39: 10.26 | F39: =D39*E39 -> 2052 | G39: 0.56 | H39: 0.1 | I39: 15.77 | J39: =SUM(F39:I39) -> 2068.43 | R39: =R38+B39-J39-K39-L39+M39+N39+O39+P39 -> 84.3
A40: 41579 | K40: 6.9 | R40: =R39+B40-J40-K40-L40+M40+N40+O40+P40 -> 77.4
...

Sheet Modal-Silna
A1: EXTRATO FINANCEIRO MODAL
A2: DATA | B2: DINHEIRO | C2: ATIVO | D2: COTAS | E2: VLR COTA | F2: TOTAL | G2: TX LIQUID | H2: EMOL | I2: CORRETAGEM | J2: VLR TOTAL | K2: CUSTODIA | L2: TED | M2: RENDA | N2: DIVIDENDOS | O2: JCP | P2: SALDO DA CONTA | S2: ATIVOS | T2: QTD | U2: PREÇO | V2: TOTAL
A3: 43164 | B3: 50 | P3: =B3-J3-K3-L3+M3+N3+O3 -> 50 | S3: ABCP11 | T3: 1 | U3: 96.27 | V3: =T3*U3 -> 96.27
A4: 43165 | C4: ABCP11 | D4: 2 | E4: 16.56 | F4: =D4*E4 -> 33.12 | G4: 0 | H4: 0 | I4: 0 | J4: =SUM(F4:I4) -> 33.12 | P4: =P3+B4-J4-K4-L4+M4+N4+O4 -> 16.88 | S4: BCFF11 | T4: 8 | U4: 82.98 | V4: =T4*U4 -> 663.84
A5: 43196 | C5: ABCP11 | M5: 0.16 | P5: =P4+B5-J5-K5-L5+M5+N5+O5 -> 17.04 | S5: EDGA11 | T5: 14 | U5: 49.69 | V5: =T5*U5 -> 695.66
A6: 43228 | C6: ABCP11 | M6: 0.16 | P6: =P5+B6-J6-K6-L6+M6+N6+O6 -> 17.2 | S6: MXRF11 | T6: 105 | U6: 10.58 | V6: =T6*U6 -> 1110.9
A7: 43258 | C7: ABCP11 | M7: 0.17 | P7: =P6+B7-J7-K7-L7+M7+N7+O7 -> 17.37 | S7: SPTW11 | T7: 5 | U7: 81 | V7: =T7*U7 -> 405
A8: 43287 | C8: ABCP11 | M8: 0.17 | P8: =P7+B8-J8-K8-L8+M8+N8+O8 -> 17.54 | S8: VISC11 | T8: 3 | U8: 107.56 | V8: =T8*U8 -> 322.68
A9: 43319 | C9: ABCP11 | M9: 0.17 | P9: =P8+B9-J9-K9-L9+M9+N9+O9 -> 17.71
A10: 43353 | C10: ABCP11 | M10: 0.17 | P10: =P9+B10-J10-K10-L10+M10+N10+O10 -> 17.88 | U10: TOTAL | V10: =SUM(V3:V8) -> 3294.35
A11: 43361 | B11: 800 | P11: =P10+B11-J11-K11-L11+M11+N11+O11 -> 817.88
A12: 43362 | B12: 950 | P12: =P11+B12-J12-K12-L12+M12+N12+O12 -> 1767.88
A13: 43361 | C13: MXRF11 | D13: 50 | E13: 9.96 | F13: =D13*E13 -> 498 | G13: 0.1 | H13: 0.02 | I13: 0 | J13: =SUM(F13:I13) -> 498.12 | P13: =P12+B13-J13-K13-L13+M13+N13+O13 -> 1269.76
A14: 43361 | C14: VISC11 | D14: 3 | E14: 96.59 | F14: =D14*E14 -> 289.77 | G14: 0.11 | H14: 0.01 | I14: 0 | J14: =SUM(F14:I14) -> 289.89 | P14: =P13+B14-J14-K14-L14+M14+N14+O14 -> 979.87
A15: 43362 | C15: EDGA11 | D15: 10 | E15: 37.01 | F15: =D15*E15 -> 370.1 | G15: 0.1 | H15: 0.02 | I15: 0 | J15: =SUM(F15:I15) -> 370.22 | P15: =P14+B15-J15-K15-L15+M15+N15+O15 -> 609.65
A16: 43362 | C16: MXRF11 | D16: 20 | E16: 9.93 | F16: =D16*E16 -> 198.6 | G16: 0.05 | H16: 0.02 | I16: 0 | J16: =SUM(F16:I16) -> 198.67 | P16: =P15+B16-J16-K16-L16+M16+N16+O16 -> 410.98
A17: 43362 | C17: SPTW11 | D17: 5 | E17: 72.35 | F17: =D17*E17 -> 361.75 | G17: 0.1 | H17: 0.02 | I17: 0 | J17: =SUM(F17:I17) -> 361.87 | P17: =P16+B17-J17-K17-L17+M17+N17+O17 -> 49.11
A18: 43006 | M18: 1.76 | P18: =P17+B18-J18-K18-L18+M18+N18+O18 -> 50.87
A19: 43378 | C19: ABCP11 | M19: 0.17 | P19: =P18+B19-J19-K19-L19+M19+N19+O19 -> 51.04
A20: 43378 | C20: SPTW11 | M20: 2.75 | P20: =P19+B20-J20-K20-L20+M20+N20+O20 -> 53.79
A21: 43388 | C21: VISC11 | M21: 1.83 | P21: =P20+B21-J21-K21-L21+M21+N21+O21 -> 55.62
A22: 43388 | C22: MXRF11 | M22: 4.9 | P22: =P21+B22-J22-K22-L22+M22+N22+O22 -> 60.52
A23: 43388 | B23: 500 | P23: =P22+B23-J23-K23-L23+M23+N23+O23 -> 560.52
A24: 43388 | C24: MXRF11 | D24: 30 | E24: 9.86 | F24: =D24*E24 -> 295.8 | G24: 0.06 | H24: 0.01 | I24: 0 | J24: =SUM(F24:I24) -> 295.87 | P24: =P23+B24-J24-K24-L24+M24+N24+O24 -> 264.65
A25: 43388 | C25: EDGA11 | D25: 4 | E25: 38.94 | F25: =D25*E25 -> 155.76 | G25: 0.06 | H25: 0.01 | I25: 0 | J25: =SUM(F25:I25) -> 155.83 | P25: =P24+B25-J25-K25-L25+M25+N25+O25 -> 108.82
A26: 43404 | C26: EDGA11 | M26: 3.07 | P26: =P25+B26-J26-K26-L26+M26+N26+O26 -> 111.89
A27: 43412 | C27: ABCP11 | M27: 0.17 | P27: =P26+B27-J27-K27-L27+M27+N27+O27 -> 112.06
A28: 43412 | C28: SPTW11 | M28: 2.75 | P28: =P27+B28-J28-K28-L28+M28+N28+O28 -> 114.81
A29: 43417 | B29: 500 | P29: =P28+B29-J29-K29-L29+M29+N29+O29 -> 614.81
A30: 43417 | C30: BCFF11 | D30: 7 | E30: 80.75 | F30: =D30*E30 -> 565.25 | G30: 0.15 | H30: 0.02 | I30: 0 | J30: =SUM(F30:I30) -> 565.42 | P30: =P29+B30-J30-K30-L30+M30+N30+O30 -> 49.39
A31: 43420 | C31: VISC11 | M31: 1.83 | P31: =P30+B31-J31-K31-L31+M31+N31+O31 -> 51.22
A32: 43420 | C32: MXRF11 | M32: 6 | P32: =P31+B32-J32-K32-L32+M32+N32+O32 -> 57.22
A33: 43434 | C33: EDGA11 | M33: 4.22 | P33: =P32+B33-J33-K33-L33+M33+N33+O33 -> 61.44
A34: 43439 | C34: MXRF11 | D34: 5 | E34: 10.09 | F34: =D34*E34 -> 50.45 | G34: 0.01 | H34: 0 | I34: 0 | J34: =SUM(F34:I34) -> 50.46 | P34: =P33+B34-J34-K34-L34+M34+N34+O34 -> 10.98
A35: 43441 | C35: ABCP11 | M35: 0.18 | P35: =P34+B35-J35-K35-L35+M35+N35+O35 -> 11.16
A36: 43441 | C36: SPTW11 | M36: 3.05 | P36: =P35+B36-J36-K36-L36+M36+N36+O36 -> 14.21
A37: 43448 | C37: VISC11 | M37: 1.81 | P37: =P36+B37-J37-K37-L37+M37+N37+O37 -> 16.02
A38: 43448 | C38: BCFF11 | M38: 4.06 | P38: =P37+B38-J38-K38-L38+M38+N38+O38 -> 20.08
A39: 43451 | C39: MXRF11 | M39: 6 | P39: =P38+B39-J39-K39-L39+M39+N39+O39 -> 26.08
A40: 43462 | C40: EDGA11 | M40: 4.72 | P40: =P39+B40-J40-K40-L40+M40+N40+O40 -> 30.8
...

Sheet MODAL
A1: DATA | B1: DINHEIRO | C1: ATIVO | D1: COTAS | E1: VLR COTA | F1: TOTAL | G1: TX LIQUID | H1: EMOL | I1: ISS SP | J1: CORRETAGEM | K1: VLR TOTAL | L1: CUSTODIA | M1: TED | N1: RENDA | O1: DIVIDENDOS | P1: JCP | Q1: SALDO DA CONTA
A2: 41799 | B2: 200 | Q2: =B2-K2-L2-M2+N2+O2+P2 -> 200
A3: 41810 | B3: 700 | Q3: =Q2+B3-K3-L3-M3+N3+O3+P3 -> 900
A4: 41813 | C4: ETER3 | D4: 100 | E4: 8.48 | F4: =D4*E4 -> 848 | G4: 0.23 | H4: 0.04 | J4: 8.99 | K4: =SUM(F4:J4) -> 857.26 | Q4: =Q3+B4-K4-L4-M4+N4+O4+P4 -> 42.74
A5: 41842 | B5: 500 | Q5: =Q4+B5-K5-L5-M5+N5+O5+P5 -> 542.74
A6: 41849 | C6: BBAS3 | D6: 400 | Q6: =Q5+B6-K6-L6-M6+N6+O6+P6 -> 542.74
A7: 41849 | B7: 500 | Q7: =Q6+B7-K7-L7-M7+N7+O7+P7 -> 1042.74
A8: 41850 | B8: 3000 | Q8: =Q7+B8-K8-L8-M8+N8+O8+P8 -> 4042.74
A9: 41851 | C9: ETER3 | D9: 100 | E9: 8.52 | F9: =D9*E9 -> 852 | G9: 0.23 | H9: 0.04 | J9: 8.99 | K9: =SUM(F9:J9) -> 861.26 | Q9: =Q8+B9-K9-L9-M9+N9+O9+P9 -> 3181.48
A10: 41858 | C10: ETER3 | D10: 100 | E10: 8.59 | F10: =D10*E10 -> 859 | G10: 0.23 | H10: 0.04 | J10: 8.99 | K10: =SUM(F10:J10) -> 868.26 | Q10: =Q9+B10-K10-L10-M10+N10+O10+P10 -> 2313.22
A11: 41864 | C11: VALE5 | D11: 80 | E11: 27.76 | F11: =D11*E11 -> 2220.8 | G11: 0.61 | H11: 0.11 | J11: 5.99 | K11: =SUM(F11:J11) -> 2227.51 | Q11: =Q10+B11-K11-L11-M11+N11+O11+P11 -> 85.71
A12: 41870 | C12: BBAS3 | D12: -200 | E12: 29.98 | F12: =D12*E12 -> -5996 | G12: 1.64 | H12: 0.29 | J12: 8.99 | K12: =SUM(F12:J12) -> -5985.08 | Q12: =Q11+B12-K12-L12-M12+N12+O12+P12 -> 6070.79
A13: 41876 | C13: ETER3 | D13: 200 | E13: 8.39 | F13: =D13*E13 -> 1678 | G13: 0.46 | H13: 0.08 | J13: 8.99 | K13: =SUM(F13:J13) -> 1687.53 | Q13: =Q12+B13-K13-L13-M13+N13+O13+P13 -> 4383.26
A14: 41878 | C14: VALE5 | D14: 50 | E14: 27.25 | F14: =D14*E14 -> 1362.5 | G14: 0.43 | H14: 0 | J14: 5.99 | K14: =SUM(F14:J14) -> 1368.92 | Q14: =Q13+B14-K14-L14-M14+N14+O14+P14 -> 3014.34
A15: 41879 | C15: ETER3 | O15: 39.9 | P15: 17.09 | Q15: =Q14+B15-K15-L15-M15+N15+O15+P15 -> 3071.33
A16: 41879 | C16: VALE5 | D16: 70 | E16: 26.12 | F16: =D16*E16 -> 1828.4 | G16: 0.59 | H16: 0 | J16: 5.99 | K16: =SUM(F16:J16) -> 1834.98 | Q16: =Q15+B16-K16-L16-M16+N16+O16+P16 -> 1236.35
A17: 41880 | C17: BBAS3 | O17: 15.69 | Q17: =Q16+B17-K17-L17-M17+N17+O17+P17 -> 1252.04
A18: 41883 | C18: ETER3 | D18: 100 | E18: 8.36 | F18: =D18*E18 -> 836 | G18: 0.26 | H18: 0 | J18: 8.99 | K18: =SUM(F18:J18) -> 845.25 | Q18: =Q17+B18-K18-L18-M18+N18+O18+P18 -> 406.79
A19: 41884 | C19: BBAS3 | D19: -200 | E19: 35.9 | F19: =D19*E19 -> -7180 | G19: 2.32 | H19: 0 | J19: 8.99 | K19: =SUM(F19:J19) -> -7168.69 | Q19: =Q18+B19-K19-L19-M19+N19+O19+P19 -> 7575.48
A20: 41887 | C20: VALE5 | D20: 100 | E20: 24.7 | F20: =D20*E20 -> 2470 | G20: 0.67 | H20: 0.12 | J20: 8.99 | K20: =SUM(F20:J20) -> 2479.78 | Q20: =Q19+B20-K20-L20-M20+N20+O20+P20 -> 5095.7
A21: 41887 | B21: -3500 | Q21: =Q20+B21-K21-L21-M21+N21+O21+P21 -> 1595.7
A22: 41894 | C22: ETER3 | D22: 200 | E22: 7.87 | F22: =D22*E22 -> 1574 | G22: 0.43 | H22: 0.07 | J22: 8.99 | K22: =SUM(F22:J22) -> 1583.49 | Q22: =Q21+B22-K22-L22-M22+N22+O22+P22 -> 12.21
A23: 41913 | C23: ETER3 | D23: 800 | E23: 0 | F23: =D23*E23 -> 0 | Q23: =Q22+B23-K23-L23-M23+N23+O23+P23 -> 12.21 | S23: Desdobramento da ETER3 de 1:2
A24: 41943 | C24: VALE5 | O24: 102.01 | P24: 165.97 | Q24: =Q23+B24-K24-L24-M24+N24+O24+P24 -> 280.19
A25: 41943 | B25: -280.19 | Q25: =Q24+B25-K25-L25-M25+N25+O25+P25 -> -1.7053026e-13
A26: 41970 | C26: ETER3 | O26: 106.4 | P26: 45.56 | Q26: =Q25+B26-K26-L26-M26+N26+O26+P26 -> 151.96
A27: 41971 | B27: -151.96 | Q27: =Q26+B27-K27-L27-M27+N27+O27+P27 -> -1.7053026e-13
A28: 42041 | C28: ETER3 | D28: -1600 | E28: 3.1 | F28: =D28*E28 -> -4960 | G28: 1.36 | H28: 0.24 | J28: 8.99 | K28: =SUM(F28:J28) -> -4949.41 | Q28: =Q27+B28-K28-L28-M28+N28+O28+P28 -> 4949.41
A29: 42046 | B29: -4949.41 | Q29: =Q28+B29-K29-L29-M29+N29+O29+P29 -> 9.094947e-13
A30: 42094 | C30: ETER3 | O30: 44.88 | Q30: =Q29+B30-K30-L30-M30+N30+O30+P30 -> 44.88
A31: 42124 | C31: VALE5 | O31: 153.45 | Q31: =Q30+B31-K31-L31-M31+N31+O31+P31 -> 198.33
A32: 42164 | C32: VALE5 | D32: -300 | E32: 17 | F32: =D32*E32 -> -5100 | G32: 1.36 | H32: 0.24 | J32: 8.99 | K32: =SUM(F32:J32) -> -5089.41 | Q32: 0 | S32: Ajuste de saldo
A33: TOTAL | B33: =SUM(B2:B32) -> -3981.56 | D33: =SUM(D2:D32) -> 0 | G33: =SUM(G2:G32) -> 10.82 | H33: =SUM(H2:H32) -> 1.27 | J33: =SUM(J2:J32) -> 116.86 | K33: =SUM(K2:K32) -> -8578.35 | L33: =SUM(L2:L32) -> 0 | M33: =SUM(M2:M32) -> 0 | N33: =SUM(N2:N32) -> 0 | O33: =SUM(O2:O32) -> 462.33 | P33: =SUM(P2:P32) -> 228.62
A36: 42440 | B36: 1400 | Q36: =Q32+B36-K36-L36-M36+N36+O36+P36 -> 1400
A37: 42444 | C37: PETR4 | D37: 200 | E37: 6.7 | F37: =D37*E37 -> 1340 | G37: 0.36 | H37: 0.06 | J37: 8.99 | K37: =SUM(F37:J37) -> 1349.41 | Q37: =Q36+B37-K37-L37-M37+N37+O37+P37 -> 50.59
A38: 42445 | B38: 2300 | Q38: =Q37+B38-K38-L38-M38+N38+O38+P38 -> 2350.59
A39: 42445 | C39: BBAS3 | D39: 100 | E39: 18.22 | F39: =D39*E39 -> 1822 | G39: 0.36 | H39: 0.06 | J39: 8.99 | K39: =SUM(F39:J39) -> 1831.41 | Q39: =Q38+B39-K39-L39-M39+N39+O39+P39 -> 519.18
A40: 42446 | C40: PETRD10 | D40: 100 | E40: 0.3 | F40: =D40*E40 -> 30 | G40: 0.36 | H40: 0.06 | J40: 8.99 | K40: =SUM(F40:J40) -> 39.41 | Q40: =Q39+B40-K40-L40-M40+N40+O40+P40 -> 479.77
A41: 42446 | C41: PETR4 | D41: -200 | E41: 8.14 | F41: =D41*E41 -> -1628 | K41: =SUM(F41:J41) -> -1628 | Q41: =Q40+B41-K41-L41-M41+N41+O41+P41 -> 2107.77
A42: 42452 | C42: BBAS3 | D42: -100 | E42: 21 | F42: =D42*E42 -> -2100 | G42: 1.23 | H42: 0.06 | J42: 8.99 | K42: =SUM(F42:J42) -> -2089.72 | Q42: =Q41+B42-K42-L42-M42+N42+O42+P42 -> 4197.49
...

Sheet Dividendos
A1: PROVENTOS - 2013
A2: ATIVO | B2: JANEIRO | C2: FEVEREIRO | D2: MARÇO | E2: ABRIL | F2: MAIO | G2: JUNHO | H2: JULHO | I2: AGOSTO | J2: SETEMBRO | K2: OUTUBRO | L2: NOVEMBRO | M2: DEZEMBRO | N2: TOTAL
A3: AÇÕES
A4: ABCB4 | N4: =SUM(B4:M4) -> 0
A5: BBAS3 | I5: 155.67 | J5: 53.34 | L5: 13.32 | M5: 52.65 | N5: =SUM(B5:M5) -> 274.98
A6: BVMF3 | L6: 11.83 | N6: =SUM(B6:M6) -> 11.83
A7: CMIG3 | M7: 47.09 | N7: =SUM(B7:M7) -> 47.09
A8: CMIG4 | N8: =SUM(B8:M8) -> 0
A9: ECOR3 | N9: =SUM(B9:M9) -> 0
A10: ELET3 | N10: =SUM(B10:M10) -> 0
A11: ELPL4 | N11: =SUM(B11:M11) -> 0
A12: ETER3 | N12: =SUM(B12:M12) -> 0
A13: HGTX3 | N13: =SUM(B13:M13) -> 0
A14: ITSA4 | N14: =SUM(B14:M14) -> 0
A15: KLBN4 | N15: =SUM(B15:M15) -> 0
A16: ODPV3 | J16: 5.87 | L16: 1.52 | M16: 6.31 | N16: =SUM(B16:M16) -> 13.7
A17: OIBR3 | K17: 152.43 | N17: =SUM(B17:M17) -> 152.43
A18: PETR3 | N18: =SUM(B18:M18) -> 0
A19: PETR4 | N19: =SUM(B19:M19) -> 0
A20: SULA11 | I20: 3.6 | L20: 3.6 | M20: 7.63 | N20: =SUM(B20:M20) -> 14.83
A21: SUZB5 | N21: =SUM(B21:M21) -> 0
A22: TAEE11 | N22: =SUM(B22:M22) -> 0
A23: TIET11 | N23: =SUM(B23:M23) -> 0
A24: VALE5 | N24: =SUM(B24:M24) -> 0
N25: =SUM(B25:M25) -> 0
N26: =SUM(B26:M26) -> 0
A27: TOTAIS | B27: =SUM(B4:B26) -> 0 | C27: =SUM(C4:C26) -> 0 | D27: =SUM(D4:D26) -> 0 | E27: =SUM(E4:E26) -> 0 | F27: =SUM(F4:F26) -> 0 | G27: =SUM(G4:G26) -> 0 | H27: =SUM(H4:H26) -> 0 | I27: =SUM(I4:I26) -> 159.27 | ... N27: =SUM(N4:N26) -> 514.86
N28: =SUM(B28:M28) -> 0
A29: FIIs
A30: BCFF11 | N30: =SUM(B30:M30) -> 0
A31: BPFF11 | N31: =SUM(B31:M31) -> 0
A32: EDGA11 | N32: =SUM(B32:M32) -> 0
A33: FIGS11 | N33: =SUM(B33:M33) -> 0
A34: GGRC11 | N34: =SUM(B34:M34) -> 0
A35: MXRF11 | N35: =SUM(B35:M35) -> 0
A36: RBGS11 | N36: =SUM(B36:M36) -> 0
A37: RBRR11 | N37: =SUM(B37:M37) -> 0
A38: SDIL11 | N38: =SUM(B38:M38) -> 0
A39: SPTW11 | N39: =SUM(B39:M39) -> 0
A40: VISC11 | N40: =SUM(B40:M40) -> 0
...

Sheet Plano de Metas
A1: OBJETIVOS PARA 2016 | T1: RESUMO MENSAL DOS INVESTIMENTOS EM 2016 | AL1: DESPESAS
A2: ATIVOS ATUAIS | C2: OBJETIVO EM 30/12/2016 | E2: FALTA | F2: % | G2: COTAÇÃO | H2: VL TOTAL | J2: STATUS | T2: MÊS | U2: RDB | V2: AÇÕES | W2: FI - FUND IMOB | X2: TESOURO | Y2: SERGUS | AB2: Ouro | AC2: OURO (gramas) | AD2: Criptomoedas U$ | AE2: Hasflare U$ | AF2: TOTAL
A3: ETER3 | B3: 3800 | C3: 5000 | E3: =C3-B3 -> 1200 | F3: =B3/C3 -> 0.76 | G3: 1.41 | H3: =G3*B3 -> 5358 | T3: JULHO | V3: =842+3570+1174+2082 -> 7668 | W3: 0 | X3: 600.92 | Y3: 0 | AB3: 0 | AC3: 0 | AF3: =SUM(U3:AB3) -> 8268.92
A4: CMIG3 | B4: 1800 | C4: 2000 | E4: =C4-B4 -> 200 | F4: =B4/C4 -> 0.9 | G4: 7.53 | H4: =G4*B4 -> 13554 | T4: AGOSTO | U4: 0 | V4: =2344+875+1264+1417+1308+894+864+866 -> 9832 | W4: 0 | X4: 592 | Y4: 0 | AB4: 0 | AC4: 0 | AF4: =SUM(U4:AC4) -> 10424
A5: PETR4 | B5: 100 | C5: 500 | E5: =C5-B5 -> 400 | F5: =B5/C5 -> 0.2 | G5: 15.6 | H5: =G5*B5 -> 1560 | T5: SETEMBRO | U5: 0 | V5: =2628+1691+869 -> 5188 | W5: 0 | X5: =538.15+568.05 -> 1106.2 | Y5: 0 | AB5: 0 | AC5: 0 | AF5: =SUM(U5:AC5) -> 6294.2
A6: ITSA4 | B6: 1300 | C6: 2000 | E6: =C6-B6 -> 700 | F6: =B6/C6 -> 0.65 | G6: 8.07 | H6: =G6*B6 -> 10491 | T6: OUTUBRO | U6: 0 | V6: =2090+1771+1799+1779 -> 7439 | W6: 0 | X6: 603.85 | Y6: 0 | AB6: 0 | AC6: 0 | AF6: =SUM(U6:AC6) -> 8042.85
A7: BBAS3 | B7: 100 | C7: 500 | E7: =C7-B7 -> 400 | F7: =B7/C7 -> 0.2 | G7: 25.68 | H7: =G7*B7 -> 2568 | T7: NOVEMBRO | U7: 0 | V7: =1561+903+1121+1211+883 -> 5679 | W7: 0 | X7: =450.17+585.55 -> 1035.72 | Y7: 0 | AB7: 0 | AC7: 0 | AF7: =SUM(U7:AC7) -> 6714.72
A8: TAE11 | B8: 400 | C8: 500 | E8: =C8-B8 -> 100 | F8: =B8/C8 -> 0.8 | G8: 19.6 | H8: =G8*B8 -> 7840 | T8: DEZEMBRO | U8: 0 | V8: =1559+828+802 -> 3189 | W8: 0 | X8: =295.94+360.29+602.96 -> 1259.19 | Y8: 0 | AB8: 250 | AC8: 2.05 | AF8: =SUM(U8:AB8) -> 4698.19
A9: KLBN4 | B9: 1000 | C9: 2000 | E9: =C9-B9 -> 1000 | F9: =B9/C9 -> 0.5 | G9: 2.7 | H9: =G9*B9 -> 2700 | T9: TOTAIS | U9: =SUM(U3:U8) -> 0 | V9: =SUM(V3:V8) -> 38995 | W9: 0 | X9: =SUM(X3:X8) -> 5197.88 | Y9: =SUM(Y3:Y8) -> 0 | AB9: =SUM(AB3:AB8) -> 250 | AC9: =SUM(AC3:AC8) -> 2.05 | AF9: =SUM(AF3:AF8) -> 44442.88
A10: TOTAL | B10: =SUM(B3:B9) -> 8500 | C10: =SUM(C3:C9) -> 12500 | E10: =SUM(E3:E9) -> 4000 | H10: =SUM(H3:H9) -> 44071
A12: OBJETIVOS PARA 2020 | T12: RESUMO MENSAL DOS INVESTIMENTOS EM 2017 | AL12: DESPESAS
A13: ATIVOS ATUAIS | C13: OBJETIVO EM 30/12/2019 | E13: FALTA | F13: % | G13: COTAÇÃO | H13: VL TOTAL | J13: STATUS | T13: MÊS | U13: RDB | V13: AÇÕES | W13: FI - FUND IMOB | X13: TESOURO | Y13: SERGUS | AB13: OURO | AC13: OURO (gramas) | AF13: TOTAL | AH13: CAPACIDADE DE POUPANÇA
A14: ABCB4 | B14: 861 | C14: 1000 | E14: =C14-B14 -> 139 | F14: =B14/C14 -> 0.861 | G14: 14.44 | H14: =G14*B14 -> 12432.84 | T14: JANEIRO | U14: 0 | V14: =719+852+879+1582 -> 4032 | W14: 0 | X14: 624.04 | Y14: 0 | AB14: 0 | AC14: 0 | AF14: =SUM(U14:AB14) -> 4656.04 | AH14: =AF14/(B62+B71) -> 0.33687376 | AL14: =B75-AF14 -> 9165.28
A15: BBAS3 | B15: 334 | C15: 1000 | E15: =C15-B15 -> 666 | F15: =B15/C15 -> 0.334 | G15: 34.75 | H15: =G15*B15 -> 11606.5 | T15: FEVEREIRO | U15: 0 | V15: =2967+1379+1638 -> 5984 | W15: 0 | X15: =626.97+530.62 -> 1157.59 | Y15: 0 | AB15: 0 | AC15: 0 | AF15: =SUM(U15:AB15) -> 7141.59 | AH15: =AF15/(C$62+C$71) -> 0.47801103 | AL15: =C75-AF15 -> 7798.63
A16: BCFF11 | B16: 615 | C16: 1000 | E16: =C16-B16 -> 385 | F16: =B16/C16 -> 0.615 | G16: 88.7 | H16: =G16*B16 -> 54550.5 | T16: MARÇO | U16: 0 | V16: =1010+1399+977 -> 3386 | W16: 0 | X16: =754.9+792.7 -> 1547.6 | Y16: 0 | AB16: 0 | AC16: 0 | AF16: =SUM(U16:AB16) -> 4933.6 | AH16: =AF16/(D$62+D$71) -> 0.36756029 | AL16: =D75-AF16 -> 8488.96
A17: BMEB4 | B17: 400 | C17: 500 | E17: =C17-B17 -> 100 | F17: =B17/C17 -> 0.8 | G17: 12.12 | H17: =G17*B17 -> 4848 | T17: ABRIL | U17: 0 | V17: 1319 | W17: 0 | X17: 476.82 | Y17: 0 | AB17: 0 | AC17: 0 | AF17: =SUM(U17:AB17) -> 1795.82 | AH17: =AF17/(E$62+E$71) -> 0.17065131 | AL17: =E75-AF17 -> 8727.51
A18: BPFF11 | B18: 245 | C18: 500 | E18: =C18-B18 -> 255 | F18: =B18/C18 -> 0.49 | G18: 95.8 | H18: =G18*B18 -> 23471 | T18: MAIO | U18: 0 | V18: =813+797+1795 -> 3405 | W18: 0 | X18: 1096.42 | Y18: 0 | AB18: 0 | AC18: 0 | AF18: =SUM(U18:AB18) -> 4501.42 | AH18: =AF18/(F$62+F$71) -> 0.26612127 | AL18: =F75-AF18 -> 12413.5
A19: BRSR6 | B19: 1000 | C19: 2000 | E19: =C19-B19 -> 1000 | F19: =B19/C19 -> 0.5 | G19: 14.32 | H19: =G19*B19 -> 14320 | T19: JUNHO | U19: =3000+5000+2000 -> 10000 | V19: =1953+1777 -> 3730 | W19: 0 | X19: 475.11 | Y19: 0 | AB19: 300 | AC19: 2.12 | AF19: =SUM(U19:AB19) -> 14505.11 | AH19: =AF19/(G$62+G$71) -> 1.0904392 | AL19: =G75-AF19 -> -1203.03
A20: CMIG3 | B20: 1500 | C20: 5000 | E20: =C20-B20 -> 3500 | F20: =B20/C20 -> 0.3 | G20: 11.72 | H20: =G20*B20 -> 17580 | T20: JULHO | U20: 5000 | V20: 1365 | W20: 4330 | X20: 944.29 | Y20: 0 | AB20: 350 | AC20: 2.3 | AF20: =SUM(U20:AB20) -> 11989.29 | AH20: =AF20/(H$62+H$71) -> 0.71281405 | AL20: =H75-AF20 -> 4830.37
A21: CMIG4 | B21: 100 | C21: 1000 | E21: =C21-B21 -> 900 | F21: =B21/C21 -> 0.1 | G21: 11.26 | H21: =G21*B21 -> 1126 | T21: AGOSTO | U21: 4000 | V21: 0 | W21: =3970+2090 -> 6060 | X21: 0 | Y21: 0 | AB21: 300 | AC21: 2.1 | AF21: =SUM(U21:AB21) -> 10360 | AH21: =AF21/(I$62+I$71) -> 0.59909985 | AL21: =I75-AF21 -> 6932.61
A22: ECOR3 | B22: 400 | C22: 1000 | E22: =C22-B22 -> 600 | F22: =B22/C22 -> 0.4 | G22: 14.17 | H22: =G22*B22 -> 5668 | T22: SETEMBRO | U22: 0 | V22: 2330 | W22: =2100+1750 -> 3850 | X22: 0 | Y22: 0 | AB22: 0 | AC22: 0 | AF22: =SUM(U22:AB22) -> 6180 | AH22: =AF22/(J$62+J$71) -> 0.39762634 | AL22: =J75-AF22 -> 9362.23
A23: EDGA11 | B23: 116 | C23: 200 | E23: =C23-B23 -> 84 | F23: =B23/C23 -> 0.58 | G23: 33.72 | H23: =G23*B23 -> 3911.52 | T23: OUTUBRO | U23: 2000 | V23: =768+1620 -> 2388 | W23: =1470+2274 -> 3744 | X23: 0 | Y23: 0 | AB23: 0 | AC23: 0 | AF23: =SUM(U23:AB23) -> 8132 | AH23: =AF23/(K$62+K$71) -> 0.47094089 | AL23: =K75-AF23 -> 9135.56
A24: ETER3 | B24: 550 | C24: 550 | E24: =C24-B24 -> 0 | F24: =B24/C24 -> 1 | G24: 8.59 | H24: =G24*B24 -> 4724.5 | T24: NOVEMBRO | U24: 0 | V24: =1657+1970 -> 3627 | W24: =1025+1147+2340+1010 -> 5522 | X24: 0 | Y24: 0 | AB24: 365.42 | AC24: 2.38 | AF24: =SUM(U24:AB24) -> 9514.42 | AH24: =AF24/(L$62+L$71) -> 0.56986497 | AL24: =L75-AF24 -> 7181.5
A25: FIGS11 | B25: 200 | C25: 200 | E25: =C25-B25 -> 0 | F25: =B25/C25 -> 1 | G25: 60.1 | H25: =G25*B25 -> 12020 | T25: DEZEMBRO | U25: 0 | V25: =1591+1576+836 -> 4003 | W25: =993+1184+1165+1019 -> 4361 | X25: 229.43 | Y25: 0 | AB25: 0 | AC25: 0 | AD25: =592 -> 592 | AE25: 2261.7 | AF25: =SUM(U25:AB25) -> 8593.43 | AH25: =AF25/(M$62+M$71) -> 0.51782936 | AL25: =M75-AF25 -> 8001.67
A26: GGRC11 | B26: 40 | C26: 500 | E26: =C26-B26 -> 460 | F26: =B26/C26 -> 0.08 | G26: 123.97 | H26: =G26*B26 -> 4958.8 | T26: TOTAIS | U26: =SUM(U14:U25) -> 21000 | V26: =SUM(V14:V25) -> 35569 | W26: =SUM(W14:W25) -> 27867 | X26: =SUM(X14:X25) -> 6551.3 | Y26: =SUM(Y14:Y25) -> 0 | AB26: =SUM(AB14:AB25) -> 1315.42 | AC26: =SUM(AC14:AC25) -> 8.9 | AD26: =SUM(AD14:AD25) -> 592 | AE26: =SUM(AE14:AE25) -> 2261.7 | AF26: =SUM(AF14:AF25) -> 92302.72 | AH26: =AF26/(N$62+N$71) -> 0.50400773 | AJ26: =AVERAGE(AF14:AF25) -> 7691.8933 | AL26: =N75-AF26 -> 90834.79
A27: HGRU11 | B27: 30 | C27: 200 | E27: =C27-B27 -> 170 | F27: =B27/C27 -> 0.15 | G27: 130.2 | H27: =G27*B27 -> 3906
A28: HGTX3 | B28: 0 | C28: 1000 | E28: =C28-B28 -> 1000 | F28: =B28/C28 -> 0 | G28: 28 | H28: =G28*B28 -> 0
A29: HTMX11 | B29: 10 | C29: 300 | E29: =C29-B29 -> 290 | F29: =B29/C29 -> 0.033333333 | G29: 118.51 | H29: =G29*B29 -> 1185.1 | T29: RESUMO MENSAL DOS INVESTIMENTOS EM 2018 | AL29: DESPESAS
A30: ITSA4 | B30: 3290 | C30: 5000 | E30: =C30-B30 -> 1710 | F30: =B30/C30 -> 0.658 | G30: 9.9 | H30: =G30*B30 -> 32571 | T30: MÊS | U30: RDB | V30: AÇÕES | W30: FI - FUND IMOB | X30: TESOURO | Y30: SERGUS | AB30: OURO | AC30: OURO (gramas) | AD30: Criptomoedas U$ | AE30: Hasflare U$ | AF30: TOTAL | AH30: CAPACIDADE DE POUPANÇA
A31: KLBN4 | B31: 4100 | C31: 5000 | E31: =C31-B31 -> 900 | F31: =B31/C31 -> 0.82 | G31: 3.9 | H31: =G31*B31 -> 15990 | T31: JANEIRO | U31: 0 | V31: =2032 -> 2032 | W31: =2371.5+1212 -> 3583.5 | X31: 0 | Y31: 0 | AE31: =880+660 -> 1540 | AF31: =SUM(U31:AB31) -> 5615.5 | AH31: =AF31/(B62+B71) -> 0.4062926 | AL31: =B97-AF31 -> 12533.04
A32: MALL11 | B32: 25 | C32: 500 | E32: =C32-B32 -> 475 | F32: =B32/C32 -> 0.05 | G32: 88.57 | H32: =G32*B32 -> 2214.25 | T32: FEVEREIRO | U32: 0 | V32: 1078.6 | W32: 7456.65 | X32: 1169.45 | Y32: 0 | AF32: =SUM(U32:AB32) -> 9704.7 | AH32: =AF32/(C62+C71) -> 0.64956875 | AL32: =C97-AF32 -> 11946.12
A33: MXRF11 | B33: 2122 | C33: 5000 | E33: =C33-B33 -> 2878 | F33: =B33/C33 -> 0.4244 | G33: 10.91 | H33: =G33*B33 -> 23151.02 | T33: MARÇO | U33: 0 | V33: =1887+1670 -> 3557 | W33: 8053.64 | X33: 0 | Y33: 0 | AF33: =SUM(U33:AB33) -> 11610.64 | AH33: =AF33/(D62+D71) -> 0.86500936 | AL33: =D97-AF33 -> 6072.7
A34: OIBR3 | B34: 1500 | C34: 5000 | E34: =C34-B34 -> 3500 | F34: =B34/C34 -> 0.3 | G34: 0.82 | H34: =G34*B34 -> 1230 | T34: ABRIL | U34: 0 | V34: =351 -> 351 | W34: =1672+895.6 -> 2567.6 | X34: 0 | Y34: 0 | AF34: =SUM(U34:AB34) -> 2918.6 | AH34: =AF34/(E62+E71) -> 0.27734567 | AL34: =E97-AF34 -> 12319.07
A35: OUFF11 | B35: 70 | C35: 500 | E35: =C35-B35 -> 430 | F35: =B35/C35 -> 0.14 | G35: 85 | H35: =G35*B35 -> 5950 | T35: MAIO | U35: =3000+3000 -> 6000 | V35: =945+801 -> 1746 | W35: =1074.1+1560.6+1925.5+882 -> 5442.2 | X35: =500.08+460.17+655.95 -> 1616.2 | Y35: 502.54 | AF35: =SUM(U35:AB35) -> 15306.94 | AH35: =AF35/(F62+F71) -> 0.90493718 | AL35: =F97-AF35 -> 6363.7
A36: PETR4 | B36: 200 | C36: 1000 | E36: =C36-B36 -> 800 | F36: =B36/C36 -> 0.2 | G36: 20.84 | H36: =G36*B36 -> 4168 | T36: JUNHO | U36: 2000 | V36: =1015+1782 -> 2797 | W36: =706+610.92+393.6+896.5+720+998.2 -> 4325.22 | X36: 0 | Y36: 502.54 | AF36: =SUM(U36:AB36) -> 9624.76 | AH36: =AF36/(G62+G71) -> 0.72355301 | AL36: =G97-AF36 -> 4546.67
A37: PMAM3 | B37: 100 | C37: 500 | E37: =C37-B37 -> 400 | F37: =B37/C37 -> 0.2 | G37: 13.65 | H37: =G37*B37 -> 1365 | T37: JULHO | U37: 1000 | V37: =431.7+892 -> 1323.7 | W37: =887.8+685+480+477.5+736+478.5+501.5+733.2 -> 4979.5 | X37: =490.27+295.49 -> 785.76 | Y37: =502.54+423.88 -> 926.42 | AF37: =SUM(U37:AB37) -> 9015.38 | AH37: =AF37/(H62+H71) -> 0.53600251 | AL37: =H97-AF37 -> 6432.77
A38: RBFF11 | B38: 146 | C38: 500 | E38: =C38-B38 -> 354 | F38: =B38/C38 -> 0.292 | G38: 73.45 | H38: =G38*B38 -> 10723.7 | T38: AGOSTO | U38: =1000 -> 1000 | V38: =552+895.8 -> 1447.8 | W38: =630.7+450.5+665+381+385.5+303.3+779 -> 3595 | X38: =368.86+133.07+506.23+492 -> 1500.16 | Y38: 502.54 | AF38: =SUM(U38:AB38) -> 8045.5 | AH38: =AF38/(I62+I71) -> 0.46525655 | AL38: =I97-AF38 -> 8648.9
A39: RBRR11 | B39: 60 | C39: 500 | E39: =C39-B39 -> 440 | F39: =B39/C39 -> 0.12 | G39: 99.6 | H39: =G39*B39 -> 5976 | T39: SETEMBRO | U39: 0 | V39: =721.5+717.5+485+966 -> 2890 | W39: =714.4+979.7+487.5+781.5+250+810+439.5+676.8+441.9+370.5 -> 5951.8 | X39: =496.6+533.75+475.22+407.52 -> 1913.09 | Y39: 527.65 | AF39: =SUM(U39:AB39) -> 11282.54 | AH39: =AF39/(J62+J71) -> 0.725928 | AL39: =J97-AF39 -> 6813.24
A40: RGBS11 | B40: 75 | C40: 500 | E40: =C40-B40 -> 425 | F40: =B40/C40 -> 0.15 | G40: 42.82 | H40: =G40*B40 -> 3211.5 | T40: OUTUBRO | U40: 0 | V40: =781+753.5+799 -> 2333.5 | W40: =711.5+608.79+969.1+493+436.45+335.55+9.87+616.25 -> 4180.51 | X40: 498.12 | Y40: 527.65 | AF40: =SUM(U40:AB40) -> 7539.78 | AH40: =AF40/(K62+K71) -> 0.4366442 | AL40: =K97-AF40 -> 8152.22
A41: SAPR4 | B41: 600 | C41: 500 | E41: =C41-B41 -> -100 | F41: =B41/C41 -> 1.2 | G41: 5.88 | H41: =G41*B41 -> 3528 | T41: NOVEMBRO | U41: 0 | V41: =586+1042+1597 -> 3225 | W41: =1110.06+503.6+519.5+515.83+597.6+539.94+504.75 -> 4291.28 | X41: =495.01+505.52 -> 1000.53 | Y41: 530.62 | AF41: =SUM(U41:AB41) -> 9047.43 | AH41: =AF41/(L62+L71) -> 0.54189467 | AL41: =L97-AF41 -> 6898.99
...

Sheet Passfolio
A1: CODIGO | B1: QTD | C1: OBJETIVO | D1: COMPANHIA | E1: DESCRICAO | F1: DY (%) | G1: Rendimentos | H1: Periodicidade | J1: Tot Rend | L1: Objetivo
A2: WSR | B2: 60.96 | C2: 300 | D2: Whitestone REIT | E2: Centros comerciais e residenciais e escritorios | F2: 4.83 | G2: 0.035 | H2: Mensal | J2: =B2*G2 -> 2.1336 | L2: =C2*G2 -> 10.5
A3: APLE | B3: 10.14 | C3: 100 | D3: Apple Hospitality REIT | E3: Hoteis e Moteis | F3: 1.42 | G3: 0 | J3: =B3*G3 -> 0 | L3: =C3*G3 -> 0
A4: NNN | B4: 5.53 | C4: 100 | D4: National Retail Properties | E4: Lojas comerciais | F4: 4.89 | G4: 0.52 | H4: Trimestral | I4: Fev-Mai-Ago-Nov | J4: =B4*G4 -> 2.8756 | L4: =C4*G4 -> 52
A5: GEO | B5: 30.03 | C5: 300 | D5: The GEO Group | E5: Servicos de reabilitacao (saude) | F5: 12.99 | G5: 0.34 | H5: Trimestral | I5: Fev-Abr-Jul-Out | J5: =B5*G5 -> 10.2102 | L5: =C5*G5 -> 102
A6: AGNC | B6: 15.11 | C6: 300 | D6: AGNC Investiment | E6: Financiamento imobiliario | F6: 8.93 | G6: 0.12 | H6: Mensal | J6: =B6*G6 -> 1.8132 | L6: =C6*G6 -> 36
A7: O | B7: 14.12 | C7: 100 | D7: O Realty Income Corp | E7: Varejo | F7: 4.57 | G7: 0.23 | H7: Mensal | J7: =B7*G7 -> 3.2476 | L7: =C7*G7 -> 23
A8: SRET | B8: 57.37 | C8: 100 | D8: Global X SuperDividend | E8: ETF de REITs | F8: 6.89 | G8: 0.055 | H8: Mensal | J8: =B8*G8 -> 3.15535 | L8: =C8*G8 -> 5.5
I9: TOTAL | J9: =SUM(J2:J8) -> 23.43555 | L9: =SUM(L2:L8) -> 229
I10: TOTAL MENSAL | J10: =J2+J6+J7+J8 -> 10.34975 | L10: =L2+L6+L7+L8 -> 75
A15: DIVIDENDOS
A16: CODIGO | B16: DATA | C16: VALOR | D16: IMPOSTO | E16: LIQUIDO
A17: WSR | B17: 44025 | C17: 0.52 | D17: 0.16 | E17: =C17-D17 -> 0.36
A18: AGNC | B18: 44055 | C18: 0.91 | D18: 0.27 | E18: =C18-D18 -> 0.64
A19: WSR | B19: 44057 | C19: 1.08 | D19: 0.32 | E19: =C19-D19 -> 0.76
A20: NNN | B20: 44060 | C20: 1.43 | D20: 0.43 | E20: =C20-D20 -> 1
A21: WSR | B21: 44085 | C21: 1.65 | D21: 0.5 | E21: =C21-D21 -> 1.15
A22: AGNC | B22: 44085 | C22: 1.78 | D22: 0.53 | E22: =C22-D22 -> 1.25
A23: AGNC | B23: 44116 | C23: 1.79 | D23: 0.54 | E23: =C23-D23 -> 1.25
A24: WSR | B24: 44120 | C24: 1.66 | D24: 0.5 | E24: =C24-D24 -> 1.16
A25: O | B25: 44120 | C25: 1.69 | D25: 0.51 | E25: =C25-D25 -> 1.18
A26: GEO | B26: 44130 | C26: 6.19 | D26: 1.86 | E26: =C26-D26 -> 4.33
A27: WSR | B27: 44148 | C27: 1.66 | D27: =C27*0.3 -> 0.498 | E27: =C27-D27 -> 1.162
A28: AGNC | B28: 44146 | C28: 1.8 | D28: 0.54 | E28: =C28-D28 -> 1.26
A29: O | B29: 44151 | C29: 1.7 | D29: =C29*0.3 -> 0.51 | E29: =C29-D29 -> 1.19
A30: NNN | B30: 44152 | C30: 2.85 | D30: =C30*0.3 -> 0.855 | E30: =C30-D30 -> 1.995
A31: AGNC | B31: 44175 | C31: 1.81 | D31: 0.54 | E31: =C31-D31 -> 1.27
A32: AGNC | B32: 44209 | C32: 1.81 | D32: 0.5 | E32: =C32-D32 -> 1.31
A33: WSR | B33: 44176 | C33: 1.67 | D33: 0.5 | E33: =C33-D33 -> 1.17
A34: WSR | B34: 44211 | C34: 2.13 | D34: =C34*0.3 -> 0.639 | E34: =C34-D34 -> 1.491
A35: O | B35: 44181 | C35: 2.09 | D35: =C35*0.3 -> 0.627 | E35: =C35-D35 -> 1.463
A36: O | B36: 44215 | C36: 3.31 | D36: =C36*0.3 -> 0.993 | E36: =C36-D36 -> 2.317
A37: GEO | B37: 44229 | C37: 7.51 | D37: =C37*0.3 -> 2.253 | E37: =C37-D37 -> 5.257
A38: AGNC | B38: 44237 | C38: 1.81 | D38: =C38*0.3 -> 0.543 | E38: =C38-D38 -> 1.267
A39: SRET | B39: 44239 | C39: 1.83 | D39: =C39*0.3 -> 0.549 | E39: =C39-D39 -> 1.281
A40: WSR | B40: 44239 | C40: 2.13 | D40: =C40*0.3 -> 0.639 | E40: =C40-D40 -> 1.491
A41: NNN | B41: 44244 | C41: 3.31 | D41: =C41*0.3 -> 0.993 | E41: =C41-D41 -> 2.317
A42: O | B42: 44244 | C42: 3.31 | D42: =C42*0.3 -> 0.993 | E42: =C42-D42 -> 2.317
A43: AGNC | B43: 44265 | C43: 1.81 | D43: =C43*0.3 -> 0.543 | E43: =C43-D43 -> 1.267
A44: SRET | B44: 44267 | C44: 2.87 | D44: =C44*0.3 -> 0.861 | E44: =C44-D44 -> 2.009
...

Sheet Despesas
A1: DESPESAS FIXAS
A2: DIA VENCTO | B2: CONTA | C2: DESCRICAO | D2: MAIO | E2: JUNHO | F2: JULHO | G2: AGOSTO | H2: SETEMBRO | I2: DEZEMBRO | J2: JANEIRO | K2: FEVEREIRO
A3: 3 | B3: TELEFONE | C3: Conta de telefone OI Total | D3: 259.81 | E3: 259.81 | F3: 259.81 | G3: 265.85 | H3: 277.35 | I3: 278 | J3: 278
A4: 5 | B4: CONDOMINIO | C4: Taxa do Condominio Morada do Rio | D4: 402.4 | E4: 402.4 | F4: 402.4 | G4: 402.4 | H4: 402.4 | I4: 402.4 | J4: 402.4 | K4: 402.4
A5: 6 | B5: LUZ | C5: Conta da Energisa - Condominio | D5: 87 | E5: 87 | F5: 82.68 | G5: 80.19 | H5: 90.62 | I5: 93.44 | J5: 94.83
A6: 5 | B6: INTERNET | C6: Masternet | D6: 99.9 | E6: 99.9 | F6: 99.9 | G6: 99.9 | H6: 99.9 | I6: 99.9 | J6: 99.9 | K6: 99.9
A7: 10 | B7: EDUCACAO | C7: PUC Minas EAD | D7: 290 | E7: 0 | F7: 0 | G7: 0 | H7: 0 | I7: 0 | J7: 0
A8: 18 | B8: SILNA | C8: Fatura do Cartao Mastercard | D8: 206.39 | E8: 0 | F8: 91.8 | G8: 91.8 | J8: 296.86
A9: 18 | B9: SILNA | C9: Fatura do Cartao Nubank | D9: 63.52 | E9: 0 | F9: 69.87 | G9: 402.87 | J9: 430.84
A10: 20 | B10: SILNA | C10: Psicologa | D10: 0 | E10: 360 | F10: 450 | G10: 450 | H10: 360 | I10: 360 | J10: 0
A11: 20 | B11: BANESE CARD | C11: Fatura do Cartao Banesecard | D11: 152.45 | E11: 152.45 | F11: 152.45 | G11: 161.16 | I11: 132.11 | J11: 132.11
A12: 25 | B12: NUBANK | C12: Fatura do Cartao Nubank | D12: 1084.15 | E12: 1542.18 | F12: 1343.63 | G12: 1672.64 | I12: 2885.8 | J12: 2077.92
A13: 27 | B13: LUZ | C13: Conta da Energisa - Casa | D13: 166.72 | E13: 136.6 | F13: 122.37 | G13: 130.94 | I13: 114.64
A14: 27 | B14: AGUA | C14: Conta da Deso - Condominio | D14: 37.98 | E14: 37.74 | F14: 38.49 | I14: 37.74 | J14: 71.5
A15: 30 | B15: ILNA | C15: Fatura do Cartao | E15: =222+126.96 -> 348.96 | F15: =210+120 -> 330 | G15: 0 | H15: 0 | I15: 0 | J15: 0
A16: 31 | B16: DARF | C16: Imposto de Renda | E16: 1595 | F16: 1603 | G16: 1605.65 | H16: 1608.19 | I16: 1613.26 | J16: 1618.18
C18: TOTAL | D18: =SUM(D3:D16) -> 2850.32 | E18: =SUM(E3:E16) -> 5022.04 | F18: =SUM(F3:F16) -> 5046.4 | G18: =SUM(G3:G16) -> 5363.4 | H18: =SUM(H3:H16) -> 2838.46 | I18: =SUM(I3:I16) -> 6017.29 | J18: =SUM(J3:J16) -> 5502.54

Sheet Forex
A3: DATA | B3: SALDO ANT | C3: LUCRO | D3: SALDO ATUAL | E3: P/L | F3: GIRO | G3: LUCRO | R3: DEPOSITOS | S3: VALOR | V3: RETIRADAS | W3: VALOR
A4: 42551 | B4: =B5-C4 -> 1347.29 | C4: 23.53 | D4: =B4+C4 -> 1370.82 | E4: =D4/B4-1 -> 0.017464688 | R4: 42549 | S4: 200 | T4: Credicard | V4: 42911 | W4: 78.09 | X4: Transferencia
A5: 42582 | B5: =B6-C5 -> 1370.82 | C5: -81.35 | D5: =B5+C5 -> 1289.47 | E5: =D5/B5-1 -> -0.059344042 | R5: 42673 | S5: =125+78.09 -> 203.09 | T5: Transferencia | V5: 42912 | W5: 200 | X5: Transferencia
A6: 42613 | B6: =B7-C6 -> 1289.47 | C6: 2.03 | D6: =B6+C6 -> 1291.5 | E6: =D6/B6-1 -> 0.0015742902 | R6: 42696 | S6: 300 | T6: Credicard | V6: 42930 | W6: 100 | X6: Neteller
A7: 42643 | B7: =B8-C7 -> 1291.5 | C7: 17.46 | D7: =B7+C7 -> 1308.96 | E7: =D7/B7-1 -> 0.013519164 | R7: 42697 | S7: 100 | T7: Boleto | V7: 43050 | W7: 1047.4 | X7: Transferencia
A8: 42674 | B8: =B9-C8 -> 1308.96 | C8: -37.07 | D8: =B8+C8 -> 1271.89 | E8: =D8/B8-1 -> -0.028320193 | R8: 42760 | S8: 300 | T8: Credicard | V8: 43139 | W8: 50 | X8: Banco
A9: 42704 | B9: =B10-C9 -> 1271.89 | C9: -20.43 | D9: =B9+C9 -> 1251.46 | E9: =D9/B9-1 -> -0.01606271 | R9: 42912 | S9: 100 | T9: Neteller | V9: 43157 | W9: 100 | X9: Banco
A10: 42735 | B10: =B11-C10 -> 1251.46 | C10: 33.24 | D10: =B10+C10 -> 1284.7 | E10: =D10/B10-1 -> 0.026560977 | H10: =D10/B4-1 -> -0.04645622 | I10: Em 2016 | R10: 43050 | S10: 1047.4 | T10: Transferencia | V10: 43732 | W10: 50 | X10: Bitcoin
A11: 42766 | B11: =B12-C11 -> 1284.7 | C11: 11.6 | D11: =B11+C11 -> 1296.3 | E11: =D11/B11-1 -> 0.0090293454 | R11: 43182 | S11: =3.81+76.19 -> 80 | T11: Neteller | V11: 43917 | W11: 100 | X11: Bitcoin
A12: 42794 | B12: =B13-C12 -> 1296.3 | C12: 99.29 | D12: =B12+C12 -> 1395.59 | E12: =D12/B12-1 -> 0.076594924 | R12: 43476 | S12: =14.71+1.29 -> 16 | T12: Neteller | V12: 43956 | W12: 200 | X12: Bitcoin | Y12: 1BTC = 8666
A13: 42825 | B13: =B14-C13 -> 1395.59 | C13: 31.4 | D13: =B13+C13 -> 1426.99 | E13: =D13/B13-1 -> 0.022499445 | R13: 43503 | S13: =34.65+0.35 -> 35 | T13: Bitcoin | V13: 43962 | W13: 168 | X13: Bitcoin | Y13: 1BTC = 8600
A14: 42855 | B14: =B15-C14 -> 1426.99 | C14: 88.82 | D14: =B14+C14 -> 1515.81 | E14: =D14/B14-1 -> 0.062242903 | R14: 43524 | S14: 100 | T14: Bitcoin | V14: 43980 | W14: 100 | X14: Banco
A15: 42886 | B15: =B16-C15 -> 1515.81 | C15: -18.68 | D15: =B15+C15 -> 1497.13 | E15: =D15/B15-1 -> -0.012323444 | R15: 43524 | S15: =3.83+379.17 -> 383 | T15: Bitcoin | V15: 44005 | W15: 100 | X15: Banco
A16: 42916 | B16: =B17-C16 -> 1497.13 | C16: -18.78 | D16: =B16+C16 -> 1478.35 | E16: =D16/B16-1 -> -0.012544001 | R16: 43792 | S16: 100 | T16: Boleto | V16: 44099 | W16: 100 | X16: Banco
A17: 42947 | B17: =B18-C17 -> 1478.35 | C17: 82.23 | D17: =B17+C17 -> 1560.58 | E17: =D17/B17-1 -> 0.055622823 | R17: 43823 | S17: 100 | T17: Boleto | V17: 44138 | W17: 100 | X17: Banco
A18: 42978 | B18: =B19-C18 -> 1560.58 | C18: -54.05 | D18: =B18+C18 -> 1506.53 | E18: =D18/B18-1 -> -0.034634559 | R18: 43833 | S18: 100 | T18: Boleto | V18: 44154 | W18: 100 | X18: Banco
A19: 43008 | B19: =B20-C19 -> 1506.53 | C19: 24.99 | D19: =B19+C19 -> 1531.52 | E19: =D19/B19-1 -> 0.016587788 | R19: 43867 | S19: 100 | T19: Boleto
A20: 43039 | B20: =B21-C20 -> 1531.52 | C20: 27.44 | D20: =B20+C20 -> 1558.96 | E20: =D20/B20-1 -> 0.017916841 | R20: 43897 | S20: 100 | T20: Boleto
A21: 43069 | B21: =B22-C21 -> 1558.96 | C21: 9.44 | D21: =B21+C21 -> 1568.4 | E21: =D21/B21-1 -> 0.0060553189
A22: 43100 | B22: =B23-C22 -> 1568.4 | C22: 36.53 | D22: =B22+C22 -> 1604.93 | E22: =D22/B22-1 -> 0.023291252 | H22: =D22/B11-1 -> 0.24926442 | I22: Em 2017
A23: 43131 | B23: =B24-C23 -> 1604.93 | C23: -137.33 | D23: =B23+C23 -> 1467.6 | E23: =D23/B23-1 -> -0.085567595
A24: 43159 | B24: =B25-C24 -> 1467.6 | C24: 90.65 | D24: =B24+C24 -> 1558.25 | E24: =D24/B24-1 -> 0.061767512 | R24: TOTAL | S24: =SUM(S4:S21) -> 3364.49 | V24: TOTAL | W24: =SUM(W4:W20) -> 2593.49
A25: 43190 | B25: =B26-C25 -> 1558.25 | C25: 128.38 | D25: =B25+C25 -> 1686.63 | E25: =D25/B25-1 -> 0.082387293 | R25: SALDO | S25: =S24-W24 -> 771
A26: 43220 | B26: =B27-C26 -> 1686.63 | C26: 40.25 | D26: =B26+C26 -> 1726.88 | E26: =D26/B26-1 -> 0.023864155 | R26: SALDO FLUTANTE | S26: 1573.41
A27: 43251 | B27: =B28-C27 -> 1726.88 | C27: 3.57 | D27: =B27+C27 -> 1730.45 | E27: =D27/B27-1 -> 0.0020673121 | R27: P/L | S27: =S26-S25 -> 802.41 | V27: SAQ BANCO | W27: =W8+W9+W14+W15+W16+W17+W18 -> 650
A28: 43281 | B28: =B29-C28 -> 1730.45 | C28: -257.08 | D28: =B28+C28 -> 1473.37 | E28: =D28/B28-1 -> -0.14856251 | R28: DEP BITCOIN | S28: =S13+S14+S15 -> 518 | V28: SAQ BITCOIN | W28: =W10+W11+W12+W13 -> 518
A29: 43312 | B29: =B30-C29 -> 1473.37 | C29: 50.65 | D29: =B29+C29 -> 1524.02 | E29: =D29/B29-1 -> 0.034376973
A30: 43343 | B30: =B31-C30 -> 1524.02 | C30: -355.55 | D30: =B30+C30 -> 1168.47 | E30: =D30/B30-1 -> -0.23329746
A31: 43373 | B31: =B32-C31 -> 1168.47 | C31: 50.58 | D31: =B31+C31 -> 1219.05 | E31: =D31/B31-1 -> 0.043287376
A32: 43404 | B32: =B33-C32 -> 1219.05 | C32: 47.51 | D32: =B32+C32 -> 1266.56 | E32: =D32/B32-1 -> 0.038972971
A33: 43434 | B33: =B34-C33 -> 1266.56 | C33: -45.16 | D33: =B33+C33 -> 1221.4 | E33: =D33/B33-1 -> -0.035655634
A34: 43465 | B34: =B35-C34 -> 1221.4 | C34: 60.82 | D34: =B34+C34 -> 1282.22 | E34: =D34/B34-1 -> 0.049795317 | H34: =D34/B23-1 -> -0.20107419 | I34: Em 2018
A35: 43496 | B35: =B36-C35 -> 1282.22 | C35: -284.69 | D35: =B35+C35 -> 997.53 | E35: =D35/B35-1 -> -0.22202898 | N35: MÊS/ANO | P35: LUCRO | R35: LUCRO PERCENT
A36: 43524 | B36: =B37-C36 -> 997.53 | C36: 23.5 | D36: =B36+C36 -> 1021.03 | E36: =D36/B36-1 -> 0.023558189
A37: 43555 | B37: =B38-C37 -> 1021.03 | C37: 35.95 | D37: =B37+C37 -> 1056.98 | E37: =D37/B37-1 -> 0.035209543
A38: 43585 | B38: =B39-C38 -> 1056.98 | C38: 42.65 | D38: =B38+C38 -> 1099.63 | E38: =D38/B38-1 -> 0.040350811
A39: 43616 | B39: =B40-C39 -> 1099.63 | C39: 4.64 | D39: =B39+C39 -> 1104.27 | E39: =D39/B39-1 -> 0.0042196011
A40: 43646 | B40: =B41-C40 -> 1104.27 | C40: 55.21 | D40: =B40+C40 -> 1159.48 | E40: =D40/B40-1 -> 0.04999683
A41: 43677 | B41: =B42-C41 -> 1159.48 | C41: 13.13 | D41: =B41+C41 -> 1172.61 | E41: =D41/B41-1 -> 0.011324042
A42: 43708 | B42: =B43-C42 -> 1172.61 | C42: 5.81 | D42: =B42+C42 -> 1178.42 | E42: =D42/B42-1 -> 0.004954759
...

Sheet Rentabilidade
A1: RENTABILIDADE
B2: 2017 | P2: 2018 | AE2: 2019
A3: ACOES | B3: Janeiro | C3: Fevereiro | D3: Marco | E3: Abril | F3: Maio | G3: Junho | H3: Julho | I3: Agosto | J3: Setembro | K3: Outubro | L3: Novembro | M3: Dezembro | N3: TOTAL | P3: Janeiro | Q3: Fevereiro | R3: Marco | S3: Abril | T3: Maio | U3: Junho | V3: Julho | W3: Agosto | X3: Setembro | Y3: Outubro | Z3: Novembro | AA3: Dezembro | AC3: TOTAL | AE3: Janeiro | AF3: Fevereiro | AG3: Marco | AH3: Abril | AI3: Maio | AJ3: Junho | AK3: Julho | AL3: Agosto | AM3: Setembro | AN3: Outubro | AP3: TOTAL
A4: Investido | B4: 43027 | C4: 49011 | D4: 52397 | E4: 53716 | F4: 57121 | G4: 60851 | H4: 62216 | I4: 62216 | J4: 64546 | K4: 66934 | L4: 70561 | M4: 74564 | N4: =M4 -> 74564 | P4: 76596 | Q4: 77674 | R4: 81231.6 | S4: 81582 | T4: 83328.6 | U4: 86131.16 | V4: 87449.3 | W4: 88897.1 | X4: 91787.1 | Y4: 94120.6 | Z4: =Y4+3255 -> 97375.6 | AA4: =Z4+2466 -> 99841.6 | AC4: =AA4 -> 99841.6 | AE4: =AA4+2598 -> 102439.6 | AF4: =AE4+1103.98 -> 103543.58 | AG4: =AF4+1128 -> 104671.58 | AH4: =AG4+1015 -> 105686.58 | AI4: =AH4 -> 105686.58 | AP4: =AI4 -> 105686.58
A5: Retorno | B5: 16.5 | C5: 51.16 | D5: 371.64 | E5: 162.38 | F5: 611.75 | G5: 305.7 | H5: 27.33 | I5: 446.16 | J5: 6.48 | K5: 144.62 | L5: 205.89 | M5: 428.79 | N5: =SUM(B5:M5) -> 2778.4 | P5: 0 | Q5: 243.02 | R5: =1175.42+6.95 -> 1182.37 | S5: 374.07 | T5: 938.24 | U5: 98.72 | V5: 34.12 | W5: 1085.92 | X5: 7.26 | Y5: 35.61 | Z5: 906.6 | AA5: 316.23 | AC5: =SUM(P5:AA5) -> 5222.16 | AE5: 153.8 | AF5: 517.17 | AG5: 2045.37 | AH5: 108.9 | AI5: 426.7 | AP5: =SUM(AE5:AN5) -> 3251.94 | AR5: =N5+AC5+AP5 -> 11252.5
A6: Percentual | B6: =B5/B4 -> 0.00038348014 | C6: =C5/C4 -> 0.0010438473 | D6: =D5/D4 -> 0.0070927725 | E6: =E5/E4 -> 0.0030229354 | F6: =F5/F4 -> 0.010709721 | G6: =G5/G4 -> 0.0050237465 | H6: =H5/H4 -> 0.00043927607 | I6: =I5/I4 -> 0.0071711457 | ... N6: =N5/N4 -> 0.037261949 | P6: =P5/P4 -> 0 | Q6: =Q5/Q4 -> 0.0031287175 | R6: =R5/R4 -> 0.014555542 | S6: =S5/S4 -> 0.0045852026 | T6: =T5/T4 -> 0.01125952 | U6: =U5/U4 -> 0.001146159 | V6: =V5/V4 -> 0.00039016893 | W6: =W5/W4 -> 0.012215472 | ... AA6: =AA5/AA4 -> 0.003167317 | AC6: =AC5/AC4 -> 0.05230445 | AE6: =AE5/AE4 -> 0.0015013725 | AF6: =AF5/AF4 -> 0.0049947085 | AG6: =AG5/AG4 -> 0.019540834 | AH6: =AH5/AH4 -> 0.0010304052 | AI6: =AI5/AI4 -> 0.0040374095 | AJ6: =AJ5/AJ4 -> #DIV/0! | AK6: =AK5/AK4 -> #DIV/0! | AL6: =AL5/AL4 -> #DIV/0! | ... AN6: =AN5/AN4 -> #DIV/0! | AP6: =AP5/AP4 -> 0.030769659
A7: Valor atual | G7: 66430 | H7: 71854 | I7: 73267 | J7: 77930 | K7: 80941 | L7: 76630 | M7: 81588 | N7: =L7/L4-1 -> 0.086010686 | P7: 90275.71 | Q7: 94931.53 | R7: 95899.83 | S7: 95094.16 | T7: 85862.3 | U7: 82778.7 | V7: 93873.2 | W7: 90173 | X7: 94036.5 | Y7: 118841.71 | Z7: 131431.13 | AA7: 141015.72 | AC7: =AA7/AA4-1 -> 0.41239443 | AE7: 142214.31 | AF7: 138718.96 | AG7: 138754.57 | AP7: =AN7/AN4-1 -> #DIV/0!
A10: FIIs | B10: Janeiro | C10: Fevereiro | D10: Marco | E10: Abril | F10: Maio | G10: Junho | H10: Julho | I10: Agosto | J10: Setembro | K10: Outubro | L10: Novembro | M10: Dezembro | N10: TOTAL | P10: Janeiro | Q10: Fevereiro | R10: Marco | S10: Abril | T10: Maio | U10: Junho | V10: Julho | W10: Agosto | X10: Setembro | Y10: Outubro | Z10: Novembro | AA10: Dezembro | AC10: TOTAL | AE10: Janeiro | AF10: Fevereiro | AG10: Marco | AH10: Abril | AI10: Maio | AJ10: Junho | AK10: Julho | AL10: Agosto | AM10: Setembro | AN10: Outubro | AP10: TOTAL
A11: Investido | B11: 0 | C11: 0 | D11: 0 | E11: 0 | F11: 0 | G11: 0 | H11: 4330 | I11: 10390 | J11: 14240 | K11: 17984 | L11: 23506 | M11: 27867 | N11: =M11 -> 27867 | P11: 31450.5 | Q11: 38907.15 | R11: 46960.79 | S11: 49528.39 | T11: 54970.59 | U11: 56681.11 | V11: 64275.31 | W11: 67238.41 | X11: 73822.11 | Y11: 78002.62 | Z11: =Y11+4291.28 -> 82293.9 | AA11: =Z11+1887.37 -> 84181.27 | AC11: =AA11 -> 84181.27 | AE11: =AA11+12207.7 -> 96388.97 | AF11: =AE11+9427.73 -> 105816.7 | AG11: =AF11+8789.5 -> 114606.2 | AH11: =AG11+7719.39 -> 122325.59 | AI11: =AH11+7220.65 -> 129546.24 | AP11: =AI11 -> 129546.24
A12: Retorno | B12: 0 | C12: 0 | D12: 0 | E12: 0 | F12: 0 | G12: 0 | H12: 0 | I12: 46.5 | J12: 75 | K12: 101.47 | L12: 126.22 | M12: 168.12 | N12: =SUM(B12:M12) -> 517.31 | P12: =24.4+183.18 -> 207.58 | Q12: =185.62+24.4 -> 210.02 | R12: =253.25+2.41 -> 255.66 | S12: 299.73 | T12: 307.13 | U12: 368.37 | V12: 399.14 | W12: 451.86 | X12: 498.75 | Y12: 536.8 | Z12: 584.17 | AA12: 643.83 | AC12: =SUM(P12:AA12) -> 4763.04 | AE12: 684.7 | AF12: 735.65 | AG12: 746.13 | AH12: 858.78 | AI12: 842.72 | AP12: =SUM(AE12:AN12) -> 3867.98 | AR12: =N12+AC12+AP12 -> 9148.33
A13: Percentual | H13: =H12/H11 -> 0 | I13: =I12/I11 -> 0.0044754572 | J13: =J12/J11 -> 0.0052668539 | K13: =K12/K11 -> 0.0056422375 | L13: =L12/L11 -> 0.0053696928 | M13: =M12/M11 -> 0.0060329422 | N13: =N12/N11 -> 0.018563534 | P13: =P12/P11 -> 0.006600213 | Q13: =Q12/Q11 -> 0.0053979795 | R13: =R12/R11 -> 0.0054441163 | S13: =S12/S11 -> 0.0060516807 | T13: =T12/T11 -> 0.0055871694 | U13: =U12/U11 -> 0.0064989906 | V13: =V12/V11 -> 0.0062098495 | W13: =W12/W11 -> 0.006720266 | ... AA13: =AA12/AA11 -> 0.0076481384 | AC13: =AC12/AC11 -> 0.056580757 | AE13: =AE12/AE11 -> 0.0071035099 | AF13: =AF12/AF11 -> 0.0069521163 | AG13: =AG12/AG11 -> 0.0065103808 | AH13: =AH12/AH11 -> 0.0070204444 | AI13: =AI12/AI11 -> 0.0065051676 | AJ13: =AJ12/AJ11 -> #DIV/0! | AK13: =AK12/AK11 -> #DIV/0! | AL13: =AL12/AL11 -> #DIV/0! | ... AN13: =AN12/AN11 -> #DIV/0! | AP13: =AP12/AP11 -> 0.02985791
A14: Valor atual | H14: 4330 | I14: 10533 | J14: 14360 | K14: =16931+2274 -> 19205 | L14: 25657 | M14: 30049 | N14: =M14/M11-1 -> 0.078300499 | P14: =4491.6+29336.4 -> 33828 | Q14: 39580 | R14: =5388+1021.9+1021.9+2614.5+1224.86+41366 -> 52637.16 | S14: 56507.8 | T14: 58446.4 | U14: 59394.04 | V14: 63609.68 | W14: 68305.15 | X14: 74143.55 | Y14: 83136.32 | Z14: 88650.75 | AA14: 96410.06 | AC14: =AA14/AA11-1 -> 0.14526735 | AP14: =AN14/AN11-1 -> #DIV/0!
A17: RDB | B17: Janeiro | C17: Fevereiro | D17: Marco | E17: Abril | F17: Maio | G17: Junho | H17: Julho | I17: Agosto | J17: Setembro | K17: Outubro | L17: Novembro | M17: Dezembro | N17: TOTAL | P17: Janeiro | Q17: Fevereiro | R17: Marco | S17: Abril | T17: Maio | U17: Junho | V17: Julho | W17: Agosto | X17: Setembro | Y17: Outubro | Z17: Novembro | AA17: Dezembro | AC17: TOTAL | AE17: Janeiro | AF17: Fevereiro | AG17: Marco | AH17: Abril | AI17: Maio | AJ17: Junho | AK17: Julho | AL17: Agosto | AM17: Setembro | AN17: Outubro | AP17: TOTAL
A18: Investido | G18: 25434 | H18: 30571 | I18: 34860.66 | J18: 35037.86 | K18: 37226.55 | L18: 32350 | M18: 32492 | N18: 32492 | P18: 32658.91 | Q18: 12623.05 | R18: 12674.41 | S18: 12734.02 | T18: 18790.08 | U18: 20885.86 | V18: 21982.54 | W18: 23092.46 | X18: 23180.85 | Y18: 23290.84 | AC18: =AA18 -> 0 | AP18: =AN18 -> 0
A19: Retorno | G19: 130.91 | H19: 216 | I19: 203.3 | J19: 177.2 | K19: 188.55 | L19: 163.74 | M19: 141.45 | N19: =SUM(B19:M19) -> 1221.15 | P19: 159.54 | Q19: 92.48 | R19: 53.94 | S19: 54.56 | T19: 61.11 | U19: 95.78 | V19: 106.4 | W19: 115.86 | X19: 109.05 | Y19: 127.08 | Z19: 116.16 | AA19: 25.82 | AC19: =SUM(P19:AA19) -> 1117.78 | AP19: =SUM(AE19:AN19) -> 0
A20: Percentual | G20: =G19/G18 -> 0.0051470473 | H20: =H19/H18 -> 0.0070655196 | I20: =I19/I18 -> 0.0058317886 | J20: =J19/J18 -> 0.0050573865 | K20: =K19/K18 -> 0.0050649335 | L20: =L19/L18 -> 0.0050615147 | M20: =M19/M18 -> 0.0043533793 | N20: =N19/N18 -> 0.037583097 | P20: =P19/P18 -> 0.0048850375 | Q20: =Q19/Q18 -> 0.0073262801 | R20: =R19/R18 -> 0.0042558194 | S20: =S19/S18 -> 0.0042845857 | T20: =T19/T18 -> 0.003252248 | U20: =U19/U18 -> 0.0045858777 | V20: =V19/V18 -> 0.004840205 | W20: =W19/W18 -> 0.0050172221 | ... Y20: =Y19/Y18 -> 0.0054562223 | AC20: =AC19/AC18 -> #DIV/0! | AE20: =AE19/AE18 -> #DIV/0! | AF20: =AF19/AF18 -> #DIV/0! | AG20: =AG19/AG18 -> #DIV/0! | AH20: =AH19/AH18 -> #DIV/0! | AI20: =AI19/AI18 -> #DIV/0! | AJ20: =AJ19/AJ18 -> #DIV/0! | AK20: =AK19/AK18 -> #DIV/0! | AL20: =AL19/AL18 -> #DIV/0! | ... AN20: =AN19/AN18 -> #DIV/0! | AP20: =AP19/AP18 -> #DIV/0!
A23: TESOURO | B23: Janeiro | C23: Fevereiro | D23: Marco | E23: Abril | F23: Maio | G23: Junho | H23: Julho | I23: Agosto | J23: Setembro | K23: Outubro | L23: Novembro | M23: Dezembro | N23: TOTAL | P23: Janeiro | Q23: Fevereiro | R23: Marco | S23: Abril | T23: Maio | U23: Junho | V23: Julho | W23: Agosto | X23: Setembro | Y23: Outubro | Z23: Novembro | AA23: Dezembro | AC23: TOTAL | AE23: Janeiro | AF23: Fevereiro | AG23: Marco | AH23: Abril | AI23: Maio | AJ23: Junho | AK23: Julho | AL23: Agosto | AM23: Setembro | AN23: Outubro | AP23: TOTAL
A24: Investido | B24: 5821.92 | C24: 6979.51 | D24: 8527.11 | E24: 9003.93 | F24: 10100.35 | G24: 10575.46 | H24: 11519.75 | I24: 11519.75 | J24: 11519.75 | K24: 11519.75 | L24: 11519.75 | M24: 11749.18 | N24: =M24 -> 11749.18 | P24: 11749.18 | Q24: 12918.63 | R24: 12918.63 | S24: 12918.63 | T24: 14534.83 | U24: 14535.16 | V24: 15321.19 | W24: 16821.35 | X24: 18733.84 | Y24: 19231.96 | Z24: =Y24+1000.53 -> 20232.49 | AA24: =Z24+1492.27 -> 21724.76 | AC24: =AA24 -> 21724.76 | AE24: =AA24+1064.07 -> 22788.83 | AF24: =AE24+599.72 -> 23388.55 | AP24: =AF24 -> 23388.55
A25: Retorno | C25: 161.59 | I25: 288.45 | N25: =SUM(B25:M25) -> 450.04 | Q25: 354.23 | W25: 397.23 | AC25: =SUM(P25:AB25) -> 751.46 | AE25: 256.1 | AF25: 409.15 | AP25: =SUM(AE25:AO25) -> 665.25 | AR25: =N25+AC25+AP25 -> 1866.75
A26: Percentual | C26: =C25/C24 -> 0.023152055 | I26: =I25/I24 -> 0.025039606 | N26: =N25/N24 -> 0.03830395 | Q26: =Q25/Q24 -> 0.02742009 | W26: =W25/W24 -> 0.023614633 | AC26: =AC25/AC24 -> 0.034590025 | AE26: =AE25/AE24 -> 0.011237962 | AF26: =AF25/AF24 -> 0.017493603 | AK26: =AK25/AK24 -> #DIV/0! | AL26: =AL25/AL24 -> #DIV/0! | AP26: =AP25/AP24 -> 0.028443405
AP29: =AP4+AP11+AP24 -> 258621.37
AP30: =AR5+AR12+AR25 -> 22267.58
AP32: =AP30/AP29 -> 0.086101083
A47: Aporte | B47: 10000 | D47: Taxa | E47: 0.006
S48: ATIVO | T48: INVESTIDO | U48: COTAS | X48: DYC
A49: MÊS | B49: APORTES | C49: JUROS MENSAL | D49: JUROS TOTAL | E49: ACUMULADO | S49: BCFF11 | T49: 45535.39 | U49: 590 | W49: =U49*V49 -> 0 | X49: =W49/T49 -> 0
A50: 1 | B50: =B47 -> 10000 | C50: 0 | D50: 0 | E50: =B50+D50 -> 10000 | S50: BPFF11 | T50: 14376.77 | U50: 155 | V50: 1.5 | W50: =U50*V50 -> 232.5 | X50: =W50/T50 -> 0.016171922
A51: =A50+1 -> 2 | B51: =$B$47+B50 -> 20000 | C51: =B50*$E$47 -> 60 | D51: =C51 -> 60 | E51: =B51+D51 -> 20060 | S51: EDGA11 | T51: 4123.04 | U51: 96 | V51: 0.2 | W51: =U51*V51 -> 19.2 | X51: =W51/T51 -> 0.0046567581
A52: =A51+1 -> 3 | B52: =$B$47+B51 -> 30000 | C52: =B51*$E$47 -> 120 | D52: =D51+C52 -> 180 | E52: =B52+D52 -> 30180 | S52: FIGS11 | T52: 13048.12 | U52: 190 | V52: 1.92 | W52: =U52*V52 -> 364.8 | X52: =W52/T52 -> 0.027958051
A53: =A52+1 -> 4 | B53: =$B$47+B52 -> 40000 | C53: =B52*$E$47 -> 180 | D53: =D52+C53 -> 360 | E53: =B53+D53 -> 40360 | S53: GGRC11 | T53: 4918.8 | U53: 40 | V53: 0.66 | W53: =U53*V53 -> 26.4 | X53: =W53/T53 -> 0.0053671627
A54: =A53+1 -> 5 | B54: =$B$47+B53 -> 50000 | C54: =B53*$E$47 -> 240 | D54: =D53+C54 -> 600 | E54: =B54+D54 -> 50600 | S54: HGRU11 | T54: 3200.42 | U54: 30 | V54: 0.74 | W54: =U54*V54 -> 22.2 | X54: =W54/T54 -> 0.0069365896
A55: =A54+1 -> 6 | B55: =$B$47+B54 -> 60000 | C55: =B54*$E$47 -> 300 | D55: =D54+C55 -> 900 | E55: =B55+D55 -> 60900 | S55: HTMX11 | T55: 1495.42 | U55: 10 | V55: 0.47 | W55: =U55*V55 -> 4.7 | X55: =W55/T55 -> 0.0031429297
A56: =A55+1 -> 7 | B56: =$B$47+B55 -> 70000 | C56: =B55*$E$47 -> 360 | D56: =D55+C56 -> 1260 | E56: =B56+D56 -> 71260 | S56: MALL11 | T56: 2601.24 | U56: 25 | V56: 0.34 | W56: =U56*V56 -> 8.5 | X56: =W56/T56 -> 0.0032676723
A57: =A56+1 -> 8 | B57: =$B$47+B56 -> 80000 | C57: =B56*$E$47 -> 420 | D57: =D56+C57 -> 1680 | E57: =B57+D57 -> 81680 | S57: MXRF11 | T57: 15586.23 | U57: 1442 | V57: 0.13 | W57: =U57*V57 -> 187.46 | X57: =W57/T57 -> 0.012027283
A58: =A57+1 -> 9 | B58: =$B$47+B57 -> 90000 | C58: =B57*$E$47 -> 480 | D58: =D57+C58 -> 2160 | E58: =B58+D58 -> 92160 | S58: OUFF11 | T58: 2883.91 | U58: 30 | V58: 0.55 | W58: =U58*V58 -> 16.5 | X58: =W58/T58 -> 0.0057213991
A59: =A58+1 -> 10 | B59: =$B$47+B58 -> 100000 | C59: =B58*$E$47 -> 540 | D59: =D58+C59 -> 2700 | E59: =B59+D59 -> 102700 | S59: RBGS11 | T59: 3582.9 | U59: 75 | V59: 0.31 | W59: =U59*V59 -> 23.25 | X59: =W59/T59 -> 0.0064891568
A60: =A59+1 -> 11 | B60: =$B$47+B59 -> 110000 | C60: =B59*$E$47 -> 600 | D60: =D59+C60 -> 3300 | E60: =B60+D60 -> 113300 | S60: RBRR11 | T60: 4034.85 | U60: 40 | V60: 0.55 | W60: =U60*V60 -> 22 | X60: =W60/T60 -> 0.0054524951
A61: =A60+1 -> 12 | B61: =$B$47+B60 -> 120000 | C61: =B60*$E$47 -> 660 | D61: =D60+C61 -> 3960 | E61: =B61+D61 -> 123960 | G61: 1 ano | S61: SDIL11 | T61: 8800.75 | U61: 105 | V61: 0.57 | W61: =U61*V61 -> 59.85 | X61: =W61/T61 -> 0.0068005568
A62: =A61+1 -> 13 | B62: =$B$47+B61 -> 130000 | C62: =B61*$E$47 -> 720 | D62: =D61+C62 -> 4680 | E62: =B62+D62 -> 134680 | S62: SPTW11 | T62: 6241.73 | U62: 100 | V62: 0.73 | W62: =U62*V62 -> 73 | X62: =W62/T62 -> 0.011695475
A63: =A62+1 -> 14 | B63: =$B$47+B62 -> 140000 | C63: =B62*$E$47 -> 780 | D63: =D62+C63 -> 5460 | E63: =B63+D63 -> 145460 | S63: VGIR11 | T63: 3097.48 | U63: 95 | V63: 0.6 | W63: =U63*V63 -> 57 | X63: =W63/T63 -> 0.018402056
...

Sheet Resumo_Geral
A1: RESUMO GERAL
A2: CORRETORA | B2: ATIVO | C2: COMPRAS | D2: VENDAS | E2: COTAS | F2: PREÇO MÉDIO | G2: PREÇO MÉDIO CORRETAGEM | H2: DIVIDENDOS | I2: JCP | J2: RENDA FI | K2: BÔNUS EM AÇÕES | M2: POSIÇÃO ATUAL
A3: XP | B3: BBAS3 | C3: =SUMIFS(XP!$D$3:$D$307,XP!$C$3:$C$307,B3,XP!$D$3:$D$307,">0",XP!$E$3:$E$307,">0") -> 649 | D3: =SUMIFS(XP!$D$3:$D$307,XP!$C$3:$C$307,B3,XP!$D$3:$D$307,"<0",XP!$E$3:$E$307,">0") -> -249 | E3: =SUMIF(XP!$C$3:C$307,B3,XP!$D$3:D$307) -> 0 | F3: =IF(C3<>0,(SUMIFS(XP!$F$3:$F$307,XP!$C$3:$C$307,$B3,XP!$F$3:$F$307,">0",XP!$F$3:$F$307,">0"))/$C3,0) -> 21.532157 | G3: =IF($C3<>0,(SUMIFS(XP!$J$3:$J$307,XP!$C$3:$C$307,$B3,XP!$J$3:$J$307,">0",XP!$J$3:$J$307,">0")+SUMIFS(MODAL!$K$2:$K$1644,MODAL!$C$2:$C$1644,$B3,MODAL!$K$2:$K$1644,">0",MODAL!$K$2:$K$1644,">0"))/$C3,0) -> 36.368521 | H3: =SUMIFS(XP!$N$3:$N$307,XP!$C$3:$C$307,$B3)+SUMIFS(MODAL!$O$2:$O$1644,MODAL!$C$2:$C$1644,$B3) -> 526.97 | I3: =SUMIFS(XP!$O$3:$O$307,XP!$C$3:$C$307,$B3)+SUMIFS(MODAL!$P$2:$P$1636,MODAL!$C$2:$C$1636,$B3) -> 955.24 | J3: =SUMIFS(XP!$M$3:$M$307,XP!$C$3:$C$307,$B3)+SUMIFS(MODAL!$N$2:$N$1644,MODAL!$C$2:$C$1644,$B3) -> 0 | M3: =(E3+K3)*L3 -> 0
A4: XP | B4: BCFF11B | C4: =SUMIFS(XP!$D$3:$D$307,XP!$C$3:$C$307,B4,XP!$D$3:$D$307,">0",XP!$E$3:$E$307,">0") -> 22 | D4: =SUMIFS(XP!$D$3:$D$307,XP!$C$3:$C$307,B4,XP!$D$3:$D$307,"<0",XP!$E$3:$E$307,">0") -> -22 | E4: =SUMIF(XP!$C$3:C$307,B4,XP!$D$3:D$307) -> 0 | F4: =IF(C4<>0,(SUMIFS(XP!$F$3:$F$307,XP!$C$3:$C$307,$B4,XP!$F$3:$F$307,">0",XP!$F$3:$F$307,">0"))/$C4,0) -> 129.85591 | G4: =IF($C4<>0,(SUMIFS(XP!$J$3:$J$307,XP!$C$3:$C$307,$B4,XP!$J$3:$J$307,">0",XP!$J$3:$J$307,">0")+SUMIFS(MODAL!$K$2:$K$1644,MODAL!$C$2:$C$1644,$B4,MODAL!$K$2:$K$1644,">0",MODAL!$K$2:$K$1644,">0"))/$C4,0) -> 132.15045 | H4: =SUMIFS(XP!$N$3:$N$307,XP!$C$3:$C$307,$B4)+SUMIFS(MODAL!$O$2:$O$1644,MODAL!$C$2:$C$1644,$B4) -> 0 | I4: =SUMIFS(XP!$O$3:$O$307,XP!$C$3:$C$307,$B4)+SUMIFS(MODAL!$P$2:$P$1636,MODAL!$C$2:$C$1636,$B4) -> 0 | J4: =SUMIFS(XP!$M$3:$M$307,XP!$C$3:$C$307,$B4)+SUMIFS(MODAL!$N$2:$N$1644,MODAL!$C$2:$C$1644,$B4) -> 83.31 | L4: 69.8 | M4: =(E4+K4)*L4 -> 0
B5: BVMF3 | C5: =SUMIFS(XP!$D$3:$D$307,XP!$C$3:$C$307,B5,XP!$D$3:$D$307,">0",XP!$E$3:$E$307,">0") -> 100 | D5: =SUMIFS(XP!$D$3:$D$307,XP!$C$3:$C$307,B5,XP!$D$3:$D$307,"<0",XP!$E$3:$E$307,">0") -> -100 | E5: =SUMIF(XP!$C$3:C$307,B5,XP!$D$3:D$307) -> 0 | F5: =IF(C5<>0,(SUMIFS(XP!$F$3:$F$307,XP!$C$3:$C$307,$B5,XP!$F$3:$F$307,">0",XP!$F$3:$F$307,">0"))/$C5,0) -> 11.54 | G5: =IF($C5<>0,(SUMIFS(XP!$J$3:$J$307,XP!$C$3:$C$307,$B5,XP!$J$3:$J$307,">0",XP!$J$3:$J$307,">0")+SUMIFS(MODAL!$K$2:$K$1644,MODAL!$C$2:$C$1644,$B5,MODAL!$K$2:$K$1644,">0",MODAL!$K$2:$K$1644,">0"))/$C5,0) -> 12.4902 | H5: =SUMIFS(XP!$N$3:$N$307,XP!$C$3:$C$307,$B5)+SUMIFS(MODAL!$O$2:$O$1644,MODAL!$C$2:$C$1644,$B5) -> 41.87 | I5: =SUMIFS(XP!$O$3:$O$307,XP!$C$3:$C$307,$B5)+SUMIFS(MODAL!$P$2:$P$1636,MODAL!$C$2:$C$1636,$B5) -> 0 | J5: =SUMIFS(XP!$M$3:$M$307,XP!$C$3:$C$307,$B5)+SUMIFS(MODAL!$N$2:$N$1644,MODAL!$C$2:$C$1644,$B5) -> 0 | M5: =(E5+K5)*L5 -> 0
A6: XP | B6: CMIG3 | C6: =SUMIFS(XP!$D$3:$D$307,XP!$C$3:$C$307,B6,XP!$D$3:$D$307,">0",XP!$E$3:$E$307,">0") -> 800 | D6: =SUMIFS(XP!$D$3:$D$307,XP!$C$3:$C$307,B6,XP!$D$3:$D$307,"<0",XP!$E$3:$E$307,">0") -> -800 | E6: =SUMIF(XP!$C$3:C$307,B6,XP!$D$3:D$307) -> 0 | F6: =IF(C6<>0,(SUMIFS(XP!$F$3:$F$399,XP!$C$3:$C$399,$B6,XP!$F$3:$F$399,">0",XP!$F$3:$F$399,">0"))/$C6,0) -> 11.0575 | G6: =IF($C6<>0,(SUMIFS(XP!$J$3:$J$399,XP!$C$3:$C$399,$B6,XP!$J$3:$J$399,">0",XP!$J$3:$J$399,">0"))/$C6,0) -> 11.182162 | H6: =SUMIFS(XP!$N$3:$N$307,XP!$C$3:$C$307,$B6) -> 754.64 | I6: =SUMIFS(XP!$O$3:$O$307,XP!$C$3:$C$307,$B6) -> 149.76 | J6: =SUMIFS(XP!$M$3:$M$307,XP!$C$3:$C$307,$B6)+SUMIFS(MODAL!$N$2:$N$1644,MODAL!$C$2:$C$1644,$B6) -> 0 | M6: =(E6+K6)*L6 -> 0
A7: XP | B7: CMIG4 | C7: =SUMIFS(XP!$D$3:$D$307,XP!$C$3:$C$307,B7,XP!$D$3:$D$307,">0",XP!$E$3:$E$307,">0") -> 200 | D7: =SUMIFS(XP!$D$3:$D$307,XP!$C$3:$C$307,B7,XP!$D$3:$D$307,"<0",XP!$E$3:$E$307,">0") -> -230 | E7: =SUMIF(XP!$C$3:C$307,B7,XP!$D$3:D$307) -> 0 | F7: =IF(C7<>0,(SUMIFS(XP!$F$3:$F$307,XP!$C$3:$C$307,$B7,XP!$F$3:$F$307,">0",XP!$F$3:$F$307,">0"))/$C7,0) -> 11.86 | G7: =IF($C7<>0,(SUMIFS(XP!$J$3:$J$307,XP!$C$3:$C$307,$B7,XP!$J$3:$J$307,">0",XP!$J$3:$J$307,">0")+SUMIFS(MODAL!$K$2:$K$1644,MODAL!$C$2:$C$1644,$B7,MODAL!$K$2:$K$1644,">0",MODAL!$K$2:$K$1644,">0"))/$C7,0) -> 18.80785 | H7: =SUMIFS(XP!$N$3:$N$307,XP!$C$3:$C$307,$B7)+SUMIFS(MODAL!$O$2:$O$1644,MODAL!$C$2:$C$1644,$B7) -> 103.98 | I7: =SUMIFS(XP!$O$3:$O$307,XP!$C$3:$C$307,$B7)+SUMIFS(MODAL!$P$2:$P$1636,MODAL!$C$2:$C$1636,$B7) -> 13.14 | J7: =SUMIFS(XP!$M$3:$M$307,XP!$C$3:$C$307,$B7)+SUMIFS(MODAL!$N$2:$N$1644,MODAL!$C$2:$C$1644,$B7) -> 0 | M7: =(E7+K7)*L7 -> 0
